Workbook

Sheet 10-10-2023
B1: FECHA | C1: 45209
A2: No | B2: Servicio | C2: Docidentidad | D2: Usuario | E2: Nombre | F2: Dosis | G2: Medidadosis | H2: Frecuencia | I2: Unidadfrecuencia | J2: Tto Empirico | K2: Tto Dirigido | L2: cultivo | M2: Suspender | N2: Cambiar | R2: Observacionesorden | S2: Codigo Diagnostico | T2: Diagnostico | U2: Dosis | V2: Peso(kg) | W2: ITU | X2: ITB | Y2: NEUMONIA | Z2: MENINGITIS | AA2: Dosis recetada
N3: Escalar | O3: Desescalar | P3: RXN adversa | Q3: Por dosis
A4: 1 | B4: 601-4 | C4: 1023664134 | D4: ERICK OROZCO GOMEZ | E4: AMPIcilina (Sal Sodica) x 1000 mg Polvo para Inyeccion | F4: 400 | G4: MG | H4: 6 | I4: H | S4: J22X | T4: INFECCION AGUDA NO ESPECIFICADA DE LAS VIAS RESPIRATORIAS INFERIORES | U4: =+V4*(W4+X4+Y4+Z4) -> 3145.5 | V4: 6.99 | W4: =IFERROR(VLOOKUP(VLOOKUP(E4,'Dosis Mx'!$R$1:$X$19,1,FALSE),'Dosis Mx'!$R$1:$X$19,6,FALSE),0) -> 0 | X4: =IFERROR(VLOOKUP(VLOOKUP(E4,'Dosis Mx'!$R$20:$X$36,1,FALSE),'Dosis Mx'!$R$20:$X$36,6,FALSE),0) -> 0 | Y4: =IFERROR(VLOOKUP(VLOOKUP(E4,'Dosis Mx'!$R$37:$X$54,1,FALSE),'Dosis Mx'!$R$37:$X$54,6,FALSE),0) -> 200 | Z4: =IFERROR(VLOOKUP(VLOOKUP(E4,'Dosis Mx'!$R$55:$X$78,1,FALSE),'Dosis Mx'!$R$55:$X$78,6,FALSE),0) -> 250 | AA4: =+F4*(24/H4) -> 1600 | AB4: 5
A5: 2 | B5: 602-2 | C5: 1025776579 | D5: JULIETA GONZALEZ CADAVID | E5: AMPIcilina 500 mg Polvo para Inyeccion | F5: 500 | G5: MG | H5: 6 | I5: H | S5: J189 | T5: NEUMONIA, NO ESPECIFICADA | U5: =+V5*(W5+X5+Y5+Z5) -> 3226.5 | V5: 7.17 | W5: =IFERROR(VLOOKUP(VLOOKUP(E5,'Dosis Mx'!$R$1:$X$19,1,FALSE),'Dosis Mx'!$R$1:$X$19,6,FALSE),0) -> 0 | X5: =IFERROR(VLOOKUP(VLOOKUP(E5,'Dosis Mx'!$R$20:$X$36,1,FALSE),'Dosis Mx'!$R$20:$X$36,6,FALSE),0) -> 0 | Y5: =IFERROR(VLOOKUP(VLOOKUP(E5,'Dosis Mx'!$R$37:$X$54,1,FALSE),'Dosis Mx'!$R$37:$X$54,6,FALSE),0) -> 200 | Z5: =IFERROR(VLOOKUP(VLOOKUP(E5,'Dosis Mx'!$R$55:$X$78,1,FALSE),'Dosis Mx'!$R$55:$X$78,6,FALSE),0) -> 250 | AA5: =+F5*(24/H5) -> 2000 | AB5: 6
A6: 3 | B6: 602-3 | C6: 1021948405 | D6: ÁLAN SAMUEL VALLEJO GARCIA | E6: AMPIcilina (Sal Sodica) x 1000 mg Polvo para Inyeccion | F6: 750 | G6: MG | H6: 6 | I6: H | S6: J46X | T6: ESTADO ASMATICO | U6: =+V6*(W6+X6+Y6+Z6) -> 4140 | V6: 9.2 | W6: =IFERROR(VLOOKUP(VLOOKUP(E6,'Dosis Mx'!$R$1:$X$19,1,FALSE),'Dosis Mx'!$R$1:$X$19,6,FALSE),0) -> 0 | X6: =IFERROR(VLOOKUP(VLOOKUP(E6,'Dosis Mx'!$R$20:$X$36,1,FALSE),'Dosis Mx'!$R$20:$X$36,6,FALSE),0) -> 0 | Y6: =IFERROR(VLOOKUP(VLOOKUP(E6,'Dosis Mx'!$R$37:$X$54,1,FALSE),'Dosis Mx'!$R$37:$X$54,6,FALSE),0) -> 200 | Z6: =IFERROR(VLOOKUP(VLOOKUP(E6,'Dosis Mx'!$R$55:$X$78,1,FALSE),'Dosis Mx'!$R$55:$X$78,6,FALSE),0) -> 250 | AA6: =+F6*(24/H6) -> 3000 | AB6: 7
A7: 4 | B7: 602-5 | C7: 1032262943 | D7: SALONAE GUISAO MONTOYA | E7: AMPIcilina Sodica/SULBactam Sodico 1000/500mg Polvo para iny (Ped) | F7: 570 | G7: MG | H7: 6 | I7: H | S7: J159 | T7: NEUMONIA BACTERIANA, NO ESPECIFICADA | U7: =+V7*(W7+X7+Y7+Z7) -> 2080 | V7: 10.4 | W7: =IFERROR(VLOOKUP(VLOOKUP(E7,'Dosis Mx'!$R$1:$X$19,1,FALSE),'Dosis Mx'!$R$1:$X$19,6,FALSE),0) -> 0 | X7: =IFERROR(VLOOKUP(VLOOKUP(E7,'Dosis Mx'!$R$20:$X$36,1,FALSE),'Dosis Mx'!$R$20:$X$36,6,FALSE),0) -> 0 | Y7: =IFERROR(VLOOKUP(VLOOKUP(E7,'Dosis Mx'!$R$37:$X$54,1,FALSE),'Dosis Mx'!$R$37:$X$54,6,FALSE),0) -> 200 | Z7: =IFERROR(VLOOKUP(VLOOKUP(E7,'Dosis Mx'!$R$55:$X$78,1,FALSE),'Dosis Mx'!$R$55:$X$78,6,FALSE),0) -> 0 | AA7: =+F7*(24/H7) -> 2280 | AB7: UCI | AC7: 9
A8: 5 | B8: 603-1 | C8: 1025909844 | D8: ASHLEY VICTORIA ANGULO GARCIA | E8: AZITromicina200mg/5 ml (4%)Polvo para reconstituirx15ml | F8: 125 | G8: MG | H8: 24 | I8: H | S8: J159 | T8: NEUMONIA BACTERIANA, NO ESPECIFICADA | U8: =+V8*(W8+X8+Y8+Z8) -> 117 | V8: 15.6 | W8: =IFERROR(VLOOKUP(VLOOKUP(E8,'Dosis Mx'!$R$1:$X$19,1,FALSE),'Dosis Mx'!$R$1:$X$19,6,FALSE),0) -> 0 | X8: =IFERROR(VLOOKUP(VLOOKUP(E8,'Dosis Mx'!$R$20:$X$36,1,FALSE),'Dosis Mx'!$R$20:$X$36,6,FALSE),0) -> 0 | Y8: =IFERROR(VLOOKUP(VLOOKUP(E8,'Dosis Mx'!$R$37:$X$54,1,FALSE),'Dosis Mx'!$R$37:$X$54,6,FALSE),0) -> 7.5 | Z8: =IFERROR(VLOOKUP(VLOOKUP(E8,'Dosis Mx'!$R$55:$X$78,1,FALSE),'Dosis Mx'!$R$55:$X$78,6,FALSE),0) -> 0 | AA8: =+F8*(24/H8) -> 125 | AB8: URGENCIAS | AC8: 12
A9: 6 | B9: 603-1 | C9: 1025909844 | D9: ASHLEY VICTORIA ANGULO GARCIA | E9: AMPIcilina 500 mg Polvo para Inyeccion | F9: 625 | G9: MG | H9: 6 | I9: H | S9: J159 | T9: NEUMONIA BACTERIANA, NO ESPECIFICADA | U9: =+V9*(W9+X9+Y9+Z9) -> 7200 | V9: 16 | W9: =IFERROR(VLOOKUP(VLOOKUP(E9,'Dosis Mx'!$R$1:$X$19,1,FALSE),'Dosis Mx'!$R$1:$X$19,6,FALSE),0) -> 0 | X9: =IFERROR(VLOOKUP(VLOOKUP(E9,'Dosis Mx'!$R$20:$X$36,1,FALSE),'Dosis Mx'!$R$20:$X$36,6,FALSE),0) -> 0 | Y9: =IFERROR(VLOOKUP(VLOOKUP(E9,'Dosis Mx'!$R$37:$X$54,1,FALSE),'Dosis Mx'!$R$37:$X$54,6,FALSE),0) -> 200 | Z9: =IFERROR(VLOOKUP(VLOOKUP(E9,'Dosis Mx'!$R$55:$X$78,1,FALSE),'Dosis Mx'!$R$55:$X$78,6,FALSE),0) -> 250 | AA9: =+F9*(24/H9) -> 2500
A10: 7 | B10: 604-1 | C10: 1031946972 | D10: MAXIMILIANO AGUDELO SERNA | E10: Ceftriaxona (Sal Sodica) 1000 mg Polvo para Inyeccion | F10: 140 | G10: MG | H10: 24 | I10: H | S10: J159 | T10: NEUMONIA BACTERIANA, NO ESPECIFICADA | U10: =+V10*(W10+X10+Y10+Z10) -> 4655 | V10: 9.8 | W10: =IFERROR(VLOOKUP(VLOOKUP(E10,'Dosis Mx'!$R$1:$X$19,1,FALSE),'Dosis Mx'!$R$1:$X$19,6,FALSE),0) -> 300 | X10: =IFERROR(VLOOKUP(VLOOKUP(E10,'Dosis Mx'!$R$20:$X$36,1,FALSE),'Dosis Mx'!$R$20:$X$36,6,FALSE),0) -> 0 | Y10: =IFERROR(VLOOKUP(VLOOKUP(E10,'Dosis Mx'!$R$37:$X$54,1,FALSE),'Dosis Mx'!$R$37:$X$54,6,FALSE),0) -> 75 | Z10: =IFERROR(VLOOKUP(VLOOKUP(E10,'Dosis Mx'!$R$55:$X$78,1,FALSE),'Dosis Mx'!$R$55:$X$78,6,FALSE),0) -> 100 | AA10: =+F10*(24/H10) -> 140
A11: 8 | B11: 604-2 | C11: 1025907262 | D11: LIAM MATIAS ESPINAL RESTREPO | E11: AMPIcilina (Sal Sodica) x 1000 mg Polvo para Inyeccion | F11: 800 | G11: MG | H11: 6 | I11: H | S11: J459 | T11: ASMA, NO ESPECIFICADO | U11: =+V11*(W11+X11+Y11+Z11) -> 20475 | V11: 45.5 | W11: =IFERROR(VLOOKUP(VLOOKUP(E11,'Dosis Mx'!$R$1:$X$19,1,FALSE),'Dosis Mx'!$R$1:$X$19,6,FALSE),0) -> 0 | X11: =IFERROR(VLOOKUP(VLOOKUP(E11,'Dosis Mx'!$R$20:$X$36,1,FALSE),'Dosis Mx'!$R$20:$X$36,6,FALSE),0) -> 0 | Y11: =IFERROR(VLOOKUP(VLOOKUP(E11,'Dosis Mx'!$R$37:$X$54,1,FALSE),'Dosis Mx'!$R$37:$X$54,6,FALSE),0) -> 200 | Z11: =IFERROR(VLOOKUP(VLOOKUP(E11,'Dosis Mx'!$R$55:$X$78,1,FALSE),'Dosis Mx'!$R$55:$X$78,6,FALSE),0) -> 250 | AA11: =+F11*(24/H11) -> 3200
A12: 9 | B12: 604-3 | C12: 1032195341 | D12: ROBER ANDRES VARGAS TONCEL | E12: AMPIcilina 500 mg Polvo para Inyeccion | F12: 500 | G12: MG | H12: 6 | I12: H | S12: J459 | T12: ASMA, NO ESPECIFICADO | U12: =+V12*(W12+X12+Y12+Z12) -> 6300 | V12: 14 | W12: =IFERROR(VLOOKUP(VLOOKUP(E12,'Dosis Mx'!$R$1:$X$19,1,FALSE),'Dosis Mx'!$R$1:$X$19,6,FALSE),0) -> 0 | X12: =IFERROR(VLOOKUP(VLOOKUP(E12,'Dosis Mx'!$R$20:$X$36,1,FALSE),'Dosis Mx'!$R$20:$X$36,6,FALSE),0) -> 0 | Y12: =IFERROR(VLOOKUP(VLOOKUP(E12,'Dosis Mx'!$R$37:$X$54,1,FALSE),'Dosis Mx'!$R$37:$X$54,6,FALSE),0) -> 200 | Z12: =IFERROR(VLOOKUP(VLOOKUP(E12,'Dosis Mx'!$R$55:$X$78,1,FALSE),'Dosis Mx'!$R$55:$X$78,6,FALSE),0) -> 250 | AA12: =+F12*(24/H12) -> 2000
A13: 10 | B13: 604-5 | C13: 1025776778 | D13: AMAIA VALENCIA QUINTERO | E13: AMPIcilina Sodica/SULBactam Sodico 1000/500mg Polvo para iny (Ped) | F13: 400 | G13: MG | H13: 6 | I13: H | S13: J159 | T13: NEUMONIA BACTERIANA, NO ESPECIFICADA | U13: =+V13*(W13+X13+Y13+Z13) -> 8000 | V13: 40 | W13: =IFERROR(VLOOKUP(VLOOKUP(E13,'Dosis Mx'!$R$1:$X$19,1,FALSE),'Dosis Mx'!$R$1:$X$19,6,FALSE),0) -> 0 | X13: =IFERROR(VLOOKUP(VLOOKUP(E13,'Dosis Mx'!$R$20:$X$36,1,FALSE),'Dosis Mx'!$R$20:$X$36,6,FALSE),0) -> 0 | Y13: =IFERROR(VLOOKUP(VLOOKUP(E13,'Dosis Mx'!$R$37:$X$54,1,FALSE),'Dosis Mx'!$R$37:$X$54,6,FALSE),0) -> 200 | Z13: =IFERROR(VLOOKUP(VLOOKUP(E13,'Dosis Mx'!$R$55:$X$78,1,FALSE),'Dosis Mx'!$R$55:$X$78,6,FALSE),0) -> 0 | AA13: =+F13*(24/H13) -> 1600
A14: 11 | B14: 604-6 | C14: 1018276805 | D14: SANTIAGO GALLEGO CASTRILLON | E14: AMPIcilina Sodica/SULBactam Sodico 1000/500mg Polvo para iny (Ped) | F14: 550 | G14: MG | H14: 6 | I14: H | S14: J22X | T14: INFECCION AGUDA NO ESPECIFICADA DE LAS VIAS RESPIRATORIAS INFERIORES | U14: =+V14*(W14+X14+Y14+Z14) -> 2200 | V14: 11 | W14: =IFERROR(VLOOKUP(VLOOKUP(E14,'Dosis Mx'!$R$1:$X$19,1,FALSE),'Dosis Mx'!$R$1:$X$19,6,FALSE),0) -> 0 | X14: =IFERROR(VLOOKUP(VLOOKUP(E14,'Dosis Mx'!$R$20:$X$36,1,FALSE),'Dosis Mx'!$R$20:$X$36,6,FALSE),0) -> 0 | Y14: =IFERROR(VLOOKUP(VLOOKUP(E14,'Dosis Mx'!$R$37:$X$54,1,FALSE),'Dosis Mx'!$R$37:$X$54,6,FALSE),0) -> 200 | Z14: =IFERROR(VLOOKUP(VLOOKUP(E14,'Dosis Mx'!$R$55:$X$78,1,FALSE),'Dosis Mx'!$R$55:$X$78,6,FALSE),0) -> 0 | AA14: =+F14*(24/H14) -> 2200
A15: 12 | B15: 605-4 | C15: 1018273143 | D15: NICOL DAHIANA OSORIO ORTIZ | E15: AMPIcilina (Sal Sodica) x 1000 mg Polvo para Inyeccion | F15: 850 | G15: MG | H15: 6 | I15: H | S15: J22X | T15: INFECCION AGUDA NO ESPECIFICADA DE LAS VIAS RESPIRATORIAS INFERIORES | U15: =+V15*(W15+X15+Y15+Z15) -> 3690 | V15: 8.2 | W15: =IFERROR(VLOOKUP(VLOOKUP(E15,'Dosis Mx'!$R$1:$X$19,1,FALSE),'Dosis Mx'!$R$1:$X$19,6,FALSE),0) -> 0 | X15: =IFERROR(VLOOKUP(VLOOKUP(E15,'Dosis Mx'!$R$20:$X$36,1,FALSE),'Dosis Mx'!$R$20:$X$36,6,FALSE),0) -> 0 | Y15: =IFERROR(VLOOKUP(VLOOKUP(E15,'Dosis Mx'!$R$37:$X$54,1,FALSE),'Dosis Mx'!$R$37:$X$54,6,FALSE),0) -> 200 | Z15: =IFERROR(VLOOKUP(VLOOKUP(E15,'Dosis Mx'!$R$55:$X$78,1,FALSE),'Dosis Mx'!$R$55:$X$78,6,FALSE),0) -> 250 | AA15: =+F15*(24/H15) -> 3400
A16: 13 | B16: 605-6 | C16: 1031949871 | D16: CIELO MARIA TEQUIA BUCAMA | E16: AMPIcilina Sodica/SULBactam Sodico 1000/500mg Polvo para iny (Ped) | F16: 390 | G16: MG | H16: 6 | I16: H | S16: E440 | T16: DESNUTRICION PROTEICOCALORICA MODERADA | U16: =+V16*(W16+X16+Y16+Z16) -> 1960 | V16: 9.8 | W16: =IFERROR(VLOOKUP(VLOOKUP(E16,'Dosis Mx'!$R$1:$X$19,1,FALSE),'Dosis Mx'!$R$1:$X$19,6,FALSE),0) -> 0 | X16: =IFERROR(VLOOKUP(VLOOKUP(E16,'Dosis Mx'!$R$20:$X$36,1,FALSE),'Dosis Mx'!$R$20:$X$36,6,FALSE),0) -> 0 | Y16: =IFERROR(VLOOKUP(VLOOKUP(E16,'Dosis Mx'!$R$37:$X$54,1,FALSE),'Dosis Mx'!$R$37:$X$54,6,FALSE),0) -> 200 | Z16: =IFERROR(VLOOKUP(VLOOKUP(E16,'Dosis Mx'!$R$55:$X$78,1,FALSE),'Dosis Mx'!$R$55:$X$78,6,FALSE),0) -> 0 | AA16: =+F16*(24/H16) -> 1560
A17: 14 | B17: 606-5 | C17: 1025909918 | D17: MARIANGEL CASTAÑO POSADA | E17: AMPIcilina (Sal Sodica) x 1000 mg Polvo para Inyeccion | F17: 600 | G17: MG | H17: 6 | I17: H | S17: J189 | T17: NEUMONIA, NO ESPECIFICADA | U17: =+V17*(W17+X17+Y17+Z17) -> 7245 | V17: 16.1 | W17: =IFERROR(VLOOKUP(VLOOKUP(E17,'Dosis Mx'!$R$1:$X$19,1,FALSE),'Dosis Mx'!$R$1:$X$19,6,FALSE),0) -> 0 | X17: =IFERROR(VLOOKUP(VLOOKUP(E17,'Dosis Mx'!$R$20:$X$36,1,FALSE),'Dosis Mx'!$R$20:$X$36,6,FALSE),0) -> 0 | Y17: =IFERROR(VLOOKUP(VLOOKUP(E17,'Dosis Mx'!$R$37:$X$54,1,FALSE),'Dosis Mx'!$R$37:$X$54,6,FALSE),0) -> 200 | Z17: =IFERROR(VLOOKUP(VLOOKUP(E17,'Dosis Mx'!$R$55:$X$78,1,FALSE),'Dosis Mx'!$R$55:$X$78,6,FALSE),0) -> 250 | AA17: =+F17*(24/H17) -> 2400
A18: 15 | B18: ObsAisl 1 | C18: 23099110655662 | D18: HIJO DE EMILSE PAOLA OSORIO | E18: Oxacilina (Sal Sodica) 1000 mg Polvo para Inyeccion | F18: 100 | G18: MG | H18: 8 | I18: H | J18: I | L18: X | S18: L032 | T18: CELULITIS DE LA CARA | U18: =+V18*(W18+X18+Y18+Z18) -> 6400 | V18: 16 | W18: =IFERROR(VLOOKUP(VLOOKUP(E18,'Dosis Mx'!$R$1:$X$19,1,FALSE),'Dosis Mx'!$R$1:$X$19,6,FALSE),0) -> 0 | X18: =IFERROR(VLOOKUP(VLOOKUP(E18,'Dosis Mx'!$R$20:$X$36,1,FALSE),'Dosis Mx'!$R$20:$X$36,6,FALSE),0) -> 200 | Y18: =IFERROR(VLOOKUP(VLOOKUP(E18,'Dosis Mx'!$R$37:$X$54,1,FALSE),'Dosis Mx'!$R$37:$X$54,6,FALSE),0) -> 0 | Z18: =IFERROR(VLOOKUP(VLOOKUP(E18,'Dosis Mx'!$R$55:$X$78,1,FALSE),'Dosis Mx'!$R$55:$X$78,6,FALSE),0) -> 200 | AA18: =+F18*(24/H18) -> 300
A19: 16 | B19: UCE 03 | C19: 1041633640 | D19: ANGELA MARIA POSADA GONZALEZ | E19: AZITromicina200mg/5 ml (4%)Polvo para reconstituirx15ml | F19: 500 | G19: MG | H19: 24 | I19: H | J19: I | L19: X | S19: I272 | T19: OTRAS HIPERTENSIONES PULMONARES SECUNDARIAS | U19: =+V19*(W19+X19+Y19+Z19) -> 27.75 | V19: 3.7 | W19: =IFERROR(VLOOKUP(VLOOKUP(E19,'Dosis Mx'!$R$1:$X$19,1,FALSE),'Dosis Mx'!$R$1:$X$19,6,FALSE),0) -> 0 | X19: =IFERROR(VLOOKUP(VLOOKUP(E19,'Dosis Mx'!$R$20:$X$36,1,FALSE),'Dosis Mx'!$R$20:$X$36,6,FALSE),0) -> 0 | Y19: =IFERROR(VLOOKUP(VLOOKUP(E19,'Dosis Mx'!$R$37:$X$54,1,FALSE),'Dosis Mx'!$R$37:$X$54,6,FALSE),0) -> 7.5 | Z19: =IFERROR(VLOOKUP(VLOOKUP(E19,'Dosis Mx'!$R$55:$X$78,1,FALSE),'Dosis Mx'!$R$55:$X$78,6,FALSE),0) -> 0 | AA19: =+F19*(24/H19) -> 500
A20: 17 | B20: UCE 03 | C20: 1041633640 | D20: ANGELA MARIA POSADA GONZALEZ | E20: AMPIcilina Sodica/SULBactam Sodico 1000/500mg Polvo para iny (Ped) | F20: 2000 | G20: MG | H20: 6 | I20: H | J20: I | L20: X | S20: I272 | T20: OTRAS HIPERTENSIONES PULMONARES SECUNDARIAS | U20: =+V20*(W20+X20+Y20+Z20) -> 940 | V20: 4.7 | W20: =IFERROR(VLOOKUP(VLOOKUP(E20,'Dosis Mx'!$R$1:$X$19,1,FALSE),'Dosis Mx'!$R$1:$X$19,6,FALSE),0) -> 0 | X20: =IFERROR(VLOOKUP(VLOOKUP(E20,'Dosis Mx'!$R$20:$X$36,1,FALSE),'Dosis Mx'!$R$20:$X$36,6,FALSE),0) -> 0 | Y20: =IFERROR(VLOOKUP(VLOOKUP(E20,'Dosis Mx'!$R$37:$X$54,1,FALSE),'Dosis Mx'!$R$37:$X$54,6,FALSE),0) -> 200 | Z20: =IFERROR(VLOOKUP(VLOOKUP(E20,'Dosis Mx'!$R$55:$X$78,1,FALSE),'Dosis Mx'!$R$55:$X$78,6,FALSE),0) -> 0 | AA20: =+F20*(24/H20) -> 8000
A21: 18 | B21: UCE 07 | C21: 1026004290 | D21: MARIA JOSE CASTAÑO MARIN | E21: AMPIcilina (Sal Sodica) x 1000 mg Polvo para Inyeccion | F21: 245 | G21: MG | H21: 6 | I21: H | R21: ALTA | S21: J219 | T21: BRONQUIOLITIS AGUDA, NO ESPECIFICADA | U21: =+V21*(W21+X21+Y21+Z21) -> 3195 | V21: 7.1 | W21: =IFERROR(VLOOKUP(VLOOKUP(E21,'Dosis Mx'!$R$1:$X$19,1,FALSE),'Dosis Mx'!$R$1:$X$19,6,FALSE),0) -> 0 | X21: =IFERROR(VLOOKUP(VLOOKUP(E21,'Dosis Mx'!$R$20:$X$36,1,FALSE),'Dosis Mx'!$R$20:$X$36,6,FALSE),0) -> 0 | Y21: =IFERROR(VLOOKUP(VLOOKUP(E21,'Dosis Mx'!$R$37:$X$54,1,FALSE),'Dosis Mx'!$R$37:$X$54,6,FALSE),0) -> 200 | Z21: =IFERROR(VLOOKUP(VLOOKUP(E21,'Dosis Mx'!$R$55:$X$78,1,FALSE),'Dosis Mx'!$R$55:$X$78,6,FALSE),0) -> 250 | AA21: =+F21*(24/H21) -> 980
A22: 19 | B22: UCE 08AISL | C22: 1023639296 | D22: MICHEL GRAJALES | E22: AMPIcilina Sodica/SULBactam Sodico 1000/500mg Polvo para iny (Ped) | F22: 1250 | G22: MG | H22: 6 | I22: H | J22: I | S22: J690 | T22: NEUMONITIS DEBIDA A ASPIRACION DE ALIMENTO O VOMITO | U22: =+V22*(W22+X22+Y22+Z22) -> 1700 | V22: 8.5 | W22: =IFERROR(VLOOKUP(VLOOKUP(E22,'Dosis Mx'!$R$1:$X$19,1,FALSE),'Dosis Mx'!$R$1:$X$19,6,FALSE),0) -> 0 | X22: =IFERROR(VLOOKUP(VLOOKUP(E22,'Dosis Mx'!$R$20:$X$36,1,FALSE),'Dosis Mx'!$R$20:$X$36,6,FALSE),0) -> 0 | Y22: =IFERROR(VLOOKUP(VLOOKUP(E22,'Dosis Mx'!$R$37:$X$54,1,FALSE),'Dosis Mx'!$R$37:$X$54,6,FALSE),0) -> 200 | Z22: =IFERROR(VLOOKUP(VLOOKUP(E22,'Dosis Mx'!$R$55:$X$78,1,FALSE),'Dosis Mx'!$R$55:$X$78,6,FALSE),0) -> 0 | AA22: =+F22*(24/H22) -> 5000
A23: 20 | B23: UCI 01 | C23: 1247049299 | D23: ANALIZ VICTORIA GONZALEZ FUENTES | E23: AMPIcilina Sodica/SULBactam Sodico 1000/500mg Polvo para iny (Ped) | F23: 280 | G23: MG | H23: 6 | I23: H | J23: NI | L23: X | M23: X | S23: J219 | T23: BRONQUIOLITIS AGUDA, NO ESPECIFICADA | U23: =+V23*(W23+X23+Y23+Z23) -> 1800 | V23: 9 | W23: =IFERROR(VLOOKUP(VLOOKUP(E23,'Dosis Mx'!$R$1:$X$19,1,FALSE),'Dosis Mx'!$R$1:$X$19,6,FALSE),0) -> 0 | X23: =IFERROR(VLOOKUP(VLOOKUP(E23,'Dosis Mx'!$R$20:$X$36,1,FALSE),'Dosis Mx'!$R$20:$X$36,6,FALSE),0) -> 0 | Y23: =IFERROR(VLOOKUP(VLOOKUP(E23,'Dosis Mx'!$R$37:$X$54,1,FALSE),'Dosis Mx'!$R$37:$X$54,6,FALSE),0) -> 200 | Z23: =IFERROR(VLOOKUP(VLOOKUP(E23,'Dosis Mx'!$R$55:$X$78,1,FALSE),'Dosis Mx'!$R$55:$X$78,6,FALSE),0) -> 0 | AA23: =+F23*(24/H23) -> 1120
A24: 21 | B24: UCI 01 | C24: 1247049299 | D24: ANALIZ VICTORIA GONZALEZ FUENTES | E24: AZITromicina200mg/5 ml (4%)Polvo para reconstituirx15ml | F24: 45 | G24: MG | H24: 24 | I24: H | J24: NI | L24: X | M24: X | S24: J219 | T24: BRONQUIOLITIS AGUDA, NO ESPECIFICADA | U24: =+V24*(W24+X24+Y24+Z24) -> 49.125 | V24: 6.55 | W24: =IFERROR(VLOOKUP(VLOOKUP(E24,'Dosis Mx'!$R$1:$X$19,1,FALSE),'Dosis Mx'!$R$1:$X$19,6,FALSE),0) -> 0 | X24: =IFERROR(VLOOKUP(VLOOKUP(E24,'Dosis Mx'!$R$20:$X$36,1,FALSE),'Dosis Mx'!$R$20:$X$36,6,FALSE),0) -> 0 | Y24: =IFERROR(VLOOKUP(VLOOKUP(E24,'Dosis Mx'!$R$37:$X$54,1,FALSE),'Dosis Mx'!$R$37:$X$54,6,FALSE),0) -> 7.5 | Z24: =IFERROR(VLOOKUP(VLOOKUP(E24,'Dosis Mx'!$R$55:$X$78,1,FALSE),'Dosis Mx'!$R$55:$X$78,6,FALSE),0) -> 0 | AA24: =+F24*(24/H24) -> 45
A25: 22 | B25: UCI 02 | C25: 1011420925 | D25: ALAN CAMILO MUÑOZ ZAPATA | E25: AMPIcilina Sodica/SULBactam Sodico 1000/500mg Polvo para iny (Ped) | F25: 450 | G25: MG | H25: 6 | I25: H | J25: I | R25: 5 DÍAS | S25: J219 | T25: BRONQUIOLITIS AGUDA, NO ESPECIFICADA | U25: =+V25*(W25+X25+Y25+Z25) -> 540 | V25: 2.7 | W25: =IFERROR(VLOOKUP(VLOOKUP(E25,'Dosis Mx'!$R$1:$X$19,1,FALSE),'Dosis Mx'!$R$1:$X$19,6,FALSE),0) -> 0 | X25: =IFERROR(VLOOKUP(VLOOKUP(E25,'Dosis Mx'!$R$20:$X$36,1,FALSE),'Dosis Mx'!$R$20:$X$36,6,FALSE),0) -> 0 | Y25: =IFERROR(VLOOKUP(VLOOKUP(E25,'Dosis Mx'!$R$37:$X$54,1,FALSE),'Dosis Mx'!$R$37:$X$54,6,FALSE),0) -> 200 | Z25: =IFERROR(VLOOKUP(VLOOKUP(E25,'Dosis Mx'!$R$55:$X$78,1,FALSE),'Dosis Mx'!$R$55:$X$78,6,FALSE),0) -> 0 | AA25: =+F25*(24/H25) -> 1800
A26: 23 | B26: UCI 04 | C26: 1031944635 | D26: IKER YULIAN DAVID MARTINEZ | E26: Cefepime 1000 mg Polvo para inyeccion | F26: 200 | G26: MG | H26: 8 | I26: H | J26: I | L26: X | N26: X | R26: 7 DÍAS | S26: I272 | T26: OTRAS HIPERTENSIONES PULMONARES SECUNDARIAS | U26: =+V26*(W26+X26+Y26+Z26) -> 0 | W26: =IFERROR(VLOOKUP(VLOOKUP(E26,'Dosis Mx'!$R$1:$X$19,1,FALSE),'Dosis Mx'!$R$1:$X$19,6,FALSE),0) -> 90 | X26: =IFERROR(VLOOKUP(VLOOKUP(E26,'Dosis Mx'!$R$20:$X$36,1,FALSE),'Dosis Mx'!$R$20:$X$36,6,FALSE),0) -> 0 | Y26: =IFERROR(VLOOKUP(VLOOKUP(E26,'Dosis Mx'!$R$37:$X$54,1,FALSE),'Dosis Mx'!$R$37:$X$54,6,FALSE),0) -> 0 | Z26: =IFERROR(VLOOKUP(VLOOKUP(E26,'Dosis Mx'!$R$55:$X$78,1,FALSE),'Dosis Mx'!$R$55:$X$78,6,FALSE),0) -> 150 | AA26: =+F26*(24/H26) -> 600
A27: 24 | B27: UCI 05 | C27: 1023544374 | D27: SANTIAGO GONZALEZ OSORIO | E27: Vancomicina (Clorhidrato) 500 mg Polvo para Inyeccion | F27: 190 | G27: MG | H27: 6 | I27: H | J27: I | L27: X | M27: X | S27: Q213 | T27: TETRALOGIA DE FALLOT | U27: =+V27*(W27+X27+Y27+Z27) -> 0 | W27: =IFERROR(VLOOKUP(VLOOKUP(E27,'Dosis Mx'!$R$1:$X$19,1,FALSE),'Dosis Mx'!$R$1:$X$19,6,FALSE),0) -> 0 | X27: =IFERROR(VLOOKUP(VLOOKUP(E27,'Dosis Mx'!$R$20:$X$36,1,FALSE),'Dosis Mx'!$R$20:$X$36,6,FALSE),0) -> 60 | Y27: =IFERROR(VLOOKUP(VLOOKUP(E27,'Dosis Mx'!$R$37:$X$54,1,FALSE),'Dosis Mx'!$R$37:$X$54,6,FALSE),0) -> 60 | Z27: =IFERROR(VLOOKUP(VLOOKUP(E27,'Dosis Mx'!$R$55:$X$78,1,FALSE),'Dosis Mx'!$R$55:$X$78,6,FALSE),0) -> 60 | AA27: =+F27*(24/H27) -> 760
A28: 25 | B28: UCI 05 | C28: 1023544374 | D28: SANTIAGO GONZALEZ OSORIO | E28: Ceftriaxona (Sal Sodica) 1000 mg Polvo para Inyeccion | F28: 640 | G28: MG | H28: 12 | I28: H | J28: I | L28: X | Q28: X | R28: C/24 HORAS 75MG | S28: Q213 | T28: TETRALOGIA DE FALLOT | U28: =+V28*(W28+X28+Y28+Z28) -> 0 | W28: =IFERROR(VLOOKUP(VLOOKUP(E28,'Dosis Mx'!$R$1:$X$19,1,FALSE),'Dosis Mx'!$R$1:$X$19,6,FALSE),0) -> 300 | X28: =IFERROR(VLOOKUP(VLOOKUP(E28,'Dosis Mx'!$R$20:$X$36,1,FALSE),'Dosis Mx'!$R$20:$X$36,6,FALSE),0) -> 0 | Y28: =IFERROR(VLOOKUP(VLOOKUP(E28,'Dosis Mx'!$R$37:$X$54,1,FALSE),'Dosis Mx'!$R$37:$X$54,6,FALSE),0) -> 75 | Z28: =IFERROR(VLOOKUP(VLOOKUP(E28,'Dosis Mx'!$R$55:$X$78,1,FALSE),'Dosis Mx'!$R$55:$X$78,6,FALSE),0) -> 100 | AA28: =+F28*(24/H28) -> 1280
A29: 26 | B29: UCI 06 | C29: 1078474669 | D29: CATALINA GONZALEZ TUNAY | E29: Vancomicina (Clorhidrato) 500 mg Polvo para Inyeccion | F29: 90 | G29: MG | H29: 6 | I29: H | J29: I | L29: X | M29: X | R29: ANALISIS TB | S29: J158 | T29: OTRAS NEUMONIAS BACTERIANAS | U29: =+V29*(W29+X29+Y29+Z29) -> 0 | W29: =IFERROR(VLOOKUP(VLOOKUP(E29,'Dosis Mx'!$R$1:$X$19,1,FALSE),'Dosis Mx'!$R$1:$X$19,6,FALSE),0) -> 0 | X29: =IFERROR(VLOOKUP(VLOOKUP(E29,'Dosis Mx'!$R$20:$X$36,1,FALSE),'Dosis Mx'!$R$20:$X$36,6,FALSE),0) -> 60 | Y29: =IFERROR(VLOOKUP(VLOOKUP(E29,'Dosis Mx'!$R$37:$X$54,1,FALSE),'Dosis Mx'!$R$37:$X$54,6,FALSE),0) -> 60 | Z29: =IFERROR(VLOOKUP(VLOOKUP(E29,'Dosis Mx'!$R$55:$X$78,1,FALSE),'Dosis Mx'!$R$55:$X$78,6,FALSE),0) -> 60 | AA29: =+F29*(24/H29) -> 360
A30: 27 | B30: UCI 06 | C30: 1078474669 | D30: CATALINA GONZALEZ TUNAY | E30: Ceftriaxona (Sal Sodica) 1000 mg Polvo para Inyeccion | F30: 300 | G30: MG | H30: 12 | I30: H | J30: I | Q30: X | R30: C/24 HORAS 75MG | S30: J158 | T30: OTRAS NEUMONIAS BACTERIANAS | U30: =+V30*(W30+X30+Y30+Z30) -> 0 | W30: =IFERROR(VLOOKUP(VLOOKUP(E30,'Dosis Mx'!$R$1:$X$19,1,FALSE),'Dosis Mx'!$R$1:$X$19,6,FALSE),0) -> 300 | X30: =IFERROR(VLOOKUP(VLOOKUP(E30,'Dosis Mx'!$R$20:$X$36,1,FALSE),'Dosis Mx'!$R$20:$X$36,6,FALSE),0) -> 0 | Y30: =IFERROR(VLOOKUP(VLOOKUP(E30,'Dosis Mx'!$R$37:$X$54,1,FALSE),'Dosis Mx'!$R$37:$X$54,6,FALSE),0) -> 75 | Z30: =IFERROR(VLOOKUP(VLOOKUP(E30,'Dosis Mx'!$R$55:$X$78,1,FALSE),'Dosis Mx'!$R$55:$X$78,6,FALSE),0) -> 100 | AA30: =+F30*(24/H30) -> 600
A31: No | B31: Servicio | E31: Nombre | F31: Dosis | G31: Medidadosis | H31: Frecuencia | I31: Unidadfrecuencia | J31: Tto Empirico | K31: Tto Dirigido | L31: cultivo | M31: Suspender | N31: Cambiar | R31: Observacionesorden | S31: Codigo Diagnostico | T31: Diagnostico | U31: Dosis | V31: Peso(kg) | W31: ITU | X31: ITB | Y31: NEUMONIA | Z31: MENINGITIS | AA31: Dosis recetada
N32: Escalar | O32: Desescalar | P32: RXN adversa | Q32: Por dosis
U33: =+V33*(W33+X33+Y33+Z33) -> 0 | W33: =IFERROR(VLOOKUP(VLOOKUP(E33,'Dosis Mx'!$R$1:$X$19,1,FALSE),'Dosis Mx'!$R$1:$X$19,6,FALSE),0) -> 0 | X33: =IFERROR(VLOOKUP(VLOOKUP(E33,'Dosis Mx'!$R$20:$X$36,1,FALSE),'Dosis Mx'!$R$20:$X$36,6,FALSE),0) -> 0 | Y33: =IFERROR(VLOOKUP(VLOOKUP(E33,'Dosis Mx'!$R$37:$X$54,1,FALSE),'Dosis Mx'!$R$37:$X$54,6,FALSE),0) -> 0 | Z33: =IFERROR(VLOOKUP(VLOOKUP(E33,'Dosis Mx'!$R$55:$X$78,1,FALSE),'Dosis Mx'!$R$55:$X$78,6,FALSE),0) -> 0 | AA33: =+F33*(24/H33) -> #DIV/0!
U34: =+V34*(W34+X34+Y34+Z34) -> 0 | W34: =IFERROR(VLOOKUP(VLOOKUP(E34,'Dosis Mx'!$R$1:$X$19,1,FALSE),'Dosis Mx'!$R$1:$X$19,6,FALSE),0) -> 0 | X34: =IFERROR(VLOOKUP(VLOOKUP(E34,'Dosis Mx'!$R$20:$X$36,1,FALSE),'Dosis Mx'!$R$20:$X$36,6,FALSE),0) -> 0 | Y34: =IFERROR(VLOOKUP(VLOOKUP(E34,'Dosis Mx'!$R$37:$X$54,1,FALSE),'Dosis Mx'!$R$37:$X$54,6,FALSE),0) -> 0 | Z34: =IFERROR(VLOOKUP(VLOOKUP(E34,'Dosis Mx'!$R$55:$X$78,1,FALSE),'Dosis Mx'!$R$55:$X$78,6,FALSE),0) -> 0 | AA34: =+F34*(24/H34) -> #DIV/0!
U35: =+V35*(W35+X35+Y35+Z35) -> 0 | W35: =IFERROR(VLOOKUP(VLOOKUP(E35,'Dosis Mx'!$R$1:$X$19,1,FALSE),'Dosis Mx'!$R$1:$X$19,6,FALSE),0) -> 0 | X35: =IFERROR(VLOOKUP(VLOOKUP(E35,'Dosis Mx'!$R$20:$X$36,1,FALSE),'Dosis Mx'!$R$20:$X$36,6,FALSE),0) -> 0 | Y35: =IFERROR(VLOOKUP(VLOOKUP(E35,'Dosis Mx'!$R$37:$X$54,1,FALSE),'Dosis Mx'!$R$37:$X$54,6,FALSE),0) -> 0 | Z35: =IFERROR(VLOOKUP(VLOOKUP(E35,'Dosis Mx'!$R$55:$X$78,1,FALSE),'Dosis Mx'!$R$55:$X$78,6,FALSE),0) -> 0 | AA35: =+F35*(24/H35) -> #DIV/0!
U36: =+V36*(W36+X36+Y36+Z36) -> 0 | W36: =IFERROR(VLOOKUP(VLOOKUP(E36,'Dosis Mx'!$R$1:$X$19,1,FALSE),'Dosis Mx'!$R$1:$X$19,6,FALSE),0) -> 0 | X36: =IFERROR(VLOOKUP(VLOOKUP(E36,'Dosis Mx'!$R$20:$X$36,1,FALSE),'Dosis Mx'!$R$20:$X$36,6,FALSE),0) -> 0 | Y36: =IFERROR(VLOOKUP(VLOOKUP(E36,'Dosis Mx'!$R$37:$X$54,1,FALSE),'Dosis Mx'!$R$37:$X$54,6,FALSE),0) -> 0 | Z36: =IFERROR(VLOOKUP(VLOOKUP(E36,'Dosis Mx'!$R$55:$X$78,1,FALSE),'Dosis Mx'!$R$55:$X$78,6,FALSE),0) -> 0 | AA36: =+F36*(24/H36) -> #DIV/0!
U37: =+V37*(W37+X37+Y37+Z37) -> 0 | W37: =IFERROR(VLOOKUP(VLOOKUP(E37,'Dosis Mx'!$R$1:$X$19,1,FALSE),'Dosis Mx'!$R$1:$X$19,6,FALSE),0) -> 0 | X37: =IFERROR(VLOOKUP(VLOOKUP(E37,'Dosis Mx'!$R$20:$X$36,1,FALSE),'Dosis Mx'!$R$20:$X$36,6,FALSE),0) -> 0 | Y37: =IFERROR(VLOOKUP(VLOOKUP(E37,'Dosis Mx'!$R$37:$X$54,1,FALSE),'Dosis Mx'!$R$37:$X$54,6,FALSE),0) -> 0 | Z37: =IFERROR(VLOOKUP(VLOOKUP(E37,'Dosis Mx'!$R$55:$X$78,1,FALSE),'Dosis Mx'!$R$55:$X$78,6,FALSE),0) -> 0 | AA37: =+F37*(24/H37) -> #DIV/0!
U38: =+V38*(W38+X38+Y38+Z38) -> 0 | W38: =IFERROR(VLOOKUP(VLOOKUP(E38,'Dosis Mx'!$R$1:$X$19,1,FALSE),'Dosis Mx'!$R$1:$X$19,6,FALSE),0) -> 0 | X38: =IFERROR(VLOOKUP(VLOOKUP(E38,'Dosis Mx'!$R$20:$X$36,1,FALSE),'Dosis Mx'!$R$20:$X$36,6,FALSE),0) -> 0 | Y38: =IFERROR(VLOOKUP(VLOOKUP(E38,'Dosis Mx'!$R$37:$X$54,1,FALSE),'Dosis Mx'!$R$37:$X$54,6,FALSE),0) -> 0 | Z38: =IFERROR(VLOOKUP(VLOOKUP(E38,'Dosis Mx'!$R$55:$X$78,1,FALSE),'Dosis Mx'!$R$55:$X$78,6,FALSE),0) -> 0 | AA38: =+F38*(24/H38) -> #DIV/0!
U39: =+V39*(W39+X39+Y39+Z39) -> 0 | W39: =IFERROR(VLOOKUP(VLOOKUP(E39,'Dosis Mx'!$R$1:$X$19,1,FALSE),'Dosis Mx'!$R$1:$X$19,6,FALSE),0) -> 0 | X39: =IFERROR(VLOOKUP(VLOOKUP(E39,'Dosis Mx'!$R$20:$X$36,1,FALSE),'Dosis Mx'!$R$20:$X$36,6,FALSE),0) -> 0 | Y39: =IFERROR(VLOOKUP(VLOOKUP(E39,'Dosis Mx'!$R$37:$X$54,1,FALSE),'Dosis Mx'!$R$37:$X$54,6,FALSE),0) -> 0 | Z39: =IFERROR(VLOOKUP(VLOOKUP(E39,'Dosis Mx'!$R$55:$X$78,1,FALSE),'Dosis Mx'!$R$55:$X$78,6,FALSE),0) -> 0 | AA39: =+F39*(24/H39) -> #DIV/0!
U40: =+V40*(W40+X40+Y40+Z40) -> 0 | W40: =IFERROR(VLOOKUP(VLOOKUP(E40,'Dosis Mx'!$R$1:$X$19,1,FALSE),'Dosis Mx'!$R$1:$X$19,6,FALSE),0) -> 0 | X40: =IFERROR(VLOOKUP(VLOOKUP(E40,'Dosis Mx'!$R$20:$X$36,1,FALSE),'Dosis Mx'!$R$20:$X$36,6,FALSE),0) -> 0 | Y40: =IFERROR(VLOOKUP(VLOOKUP(E40,'Dosis Mx'!$R$37:$X$54,1,FALSE),'Dosis Mx'!$R$37:$X$54,6,FALSE),0) -> 0 | Z40: =IFERROR(VLOOKUP(VLOOKUP(E40,'Dosis Mx'!$R$55:$X$78,1,FALSE),'Dosis Mx'!$R$55:$X$78,6,FALSE),0) -> 0 | AA40: =+F40*(24/H40) -> #DIV/0!
...

Sheet 13-10-2023
B1: FECHA | C1: 45212
A2: No | B2: Servicio | C2: Docidentidad | D2: Usuario | E2: Nombre | F2: Dosis | G2: Medidadosis | H2: Frecuencia | I2: Unidadfrecuencia | J2: Tto Empirico | K2: Tto Dirigido | L2: cultivo | M2: Suspender | N2: Cambiar | R2: Observacionesorden | S2: Codigo Diagnostico | T2: Diagnostico | U2: Dosis | V2: Peso(kg) | W2: ITU | X2: ITB | Y2: NEUMONIA | Z2: MENINGITIS | AA2: Dosis recetada
N3: Escalar | O3: Desescalar | P3: RXN adversa | Q3: Por dosis
A4: 1 | B4: 501-4 | C4: 1038550461 | D4: ADHARA GALEANO | E4: Clindamicina (Fosfato) 600 mg /4ml Solucion Inyectable | F4: 70 | G4: MG | H4: 6 | I4: H | J4: I | S4: L029 | T4: ABSCESO CUTANEO, FURUNCULO Y ANTRAX DE SITIO NO ESPECIFICADO | U4: =+V4*(W4+X4+Y4+Z4) -> 314.55 | V4: 6.99 | W4: =IFERROR(VLOOKUP(VLOOKUP(E4,'Dosis Mx'!$R$1:$X$19,1,FALSE),'Dosis Mx'!$R$1:$X$19,6,FALSE),0) -> 0 | X4: =IFERROR(VLOOKUP(VLOOKUP(E4,'Dosis Mx'!$R$20:$X$36,1,FALSE),'Dosis Mx'!$R$20:$X$36,6,FALSE),0) -> 10 | Y4: =IFERROR(VLOOKUP(VLOOKUP(E4,'Dosis Mx'!$R$37:$X$54,1,FALSE),'Dosis Mx'!$R$37:$X$54,6,FALSE),0) -> 35 | Z4: =IFERROR(VLOOKUP(VLOOKUP(E4,'Dosis Mx'!$R$55:$X$78,1,FALSE),'Dosis Mx'!$R$55:$X$78,6,FALSE),0) -> 0 | AA4: =+F4*(24/H4) -> 280 | AB4: 5 | AC4: 31
A5: 2 | B5: 502-3 | C5: 1129604154 | D5: LUCIANA LEAL TANGARIFE | E5: Nistatina 100.000 U/ml Suspension Oral Frasco X 60 ml | F5: 5 | G5: 15 | H5: 6 | I5: H | J5: NI | M5: X | S5: K121 | T5: OTRAS FORMAS DE ESTOMATITIS | U5: =+V5*(W5+X5+Y5+Z5) -> 0 | V5: 7.17 | W5: =IFERROR(VLOOKUP(VLOOKUP(E5,'Dosis Mx'!$R$1:$X$19,1,FALSE),'Dosis Mx'!$R$1:$X$19,6,FALSE),0) -> 0 | X5: =IFERROR(VLOOKUP(VLOOKUP(E5,'Dosis Mx'!$R$20:$X$36,1,FALSE),'Dosis Mx'!$R$20:$X$36,6,FALSE),0) -> 0 | Y5: =IFERROR(VLOOKUP(VLOOKUP(E5,'Dosis Mx'!$R$37:$X$54,1,FALSE),'Dosis Mx'!$R$37:$X$54,6,FALSE),0) -> 0 | Z5: =IFERROR(VLOOKUP(VLOOKUP(E5,'Dosis Mx'!$R$55:$X$78,1,FALSE),'Dosis Mx'!$R$55:$X$78,6,FALSE),0) -> 0 | AA5: =+F5*(24/H5) -> 20 | AB5: 6 | AC5: 12
A6: 3 | B6: 502-4 | C6: 1018279481 | D6: CHLOE HENAO VILLEGAS | E6: AMIKacina (Sulfato) 100 mg/2 ml Solucion Inyectable | F6: 135 | G6: MG | H6: 24 | I6: H | J6: I | L6: X | S6: N390 | T6: INFECCION DE VIAS URINARIAS, SITIO NO ESPECIFICADO | U6: =+V6*(W6+X6+Y6+Z6) -> 299 | V6: 9.2 | W6: =IFERROR(VLOOKUP(VLOOKUP(E6,'Dosis Mx'!$R$1:$X$19,1,FALSE),'Dosis Mx'!$R$1:$X$19,6,FALSE),0) -> 15 | X6: =IFERROR(VLOOKUP(VLOOKUP(E6,'Dosis Mx'!$R$20:$X$36,1,FALSE),'Dosis Mx'!$R$20:$X$36,6,FALSE),0) -> 0 | Y6: =IFERROR(VLOOKUP(VLOOKUP(E6,'Dosis Mx'!$R$37:$X$54,1,FALSE),'Dosis Mx'!$R$37:$X$54,6,FALSE),0) -> 0 | Z6: =IFERROR(VLOOKUP(VLOOKUP(E6,'Dosis Mx'!$R$55:$X$78,1,FALSE),'Dosis Mx'!$R$55:$X$78,6,FALSE),0) -> 17.5 | AA6: =+F6*(24/H6) -> 135 | AB6: 7
A7: 4 | B7: 502-5 | C7: 1022170611 | D7: LIAM DAVID GONZALEZ MARRUGO | E7: AMIKacina (Sulfato) 100 mg/2 ml Solucion Inyectable | F7: 150 | G7: MG | H7: 24 | I7: H | J7: I | L7: X | S7: F445 | T7: CONVULSIONES DISOCIATIVAS | U7: =+V7*(W7+X7+Y7+Z7) -> 338 | V7: 10.4 | W7: =IFERROR(VLOOKUP(VLOOKUP(E7,'Dosis Mx'!$R$1:$X$19,1,FALSE),'Dosis Mx'!$R$1:$X$19,6,FALSE),0) -> 15 | X7: =IFERROR(VLOOKUP(VLOOKUP(E7,'Dosis Mx'!$R$20:$X$36,1,FALSE),'Dosis Mx'!$R$20:$X$36,6,FALSE),0) -> 0 | Y7: =IFERROR(VLOOKUP(VLOOKUP(E7,'Dosis Mx'!$R$37:$X$54,1,FALSE),'Dosis Mx'!$R$37:$X$54,6,FALSE),0) -> 0 | Z7: =IFERROR(VLOOKUP(VLOOKUP(E7,'Dosis Mx'!$R$55:$X$78,1,FALSE),'Dosis Mx'!$R$55:$X$78,6,FALSE),0) -> 17.5 | AA7: =+F7*(24/H7) -> 150 | AB7: UCI
A8: 5 | B8: 503-5 | C8: 1039380512 | D8: SARAY MARTINEZ MAYA | E8: AMIKacina (Sulfato) 500 mg/2 ml Solucion Inyectable | F8: 240 | G8: MG | H8: 24 | I8: H | J8: I | L8: X | S8: N390 | T8: INFECCION DE VIAS URINARIAS, SITIO NO ESPECIFICADO | U8: =+V8*(W8+X8+Y8+Z8) -> 507 | V8: 15.6 | W8: =IFERROR(VLOOKUP(VLOOKUP(E8,'Dosis Mx'!$R$1:$X$19,1,FALSE),'Dosis Mx'!$R$1:$X$19,6,FALSE),0) -> 15 | X8: =IFERROR(VLOOKUP(VLOOKUP(E8,'Dosis Mx'!$R$20:$X$36,1,FALSE),'Dosis Mx'!$R$20:$X$36,6,FALSE),0) -> 0 | Y8: =IFERROR(VLOOKUP(VLOOKUP(E8,'Dosis Mx'!$R$37:$X$54,1,FALSE),'Dosis Mx'!$R$37:$X$54,6,FALSE),0) -> 0 | Z8: =IFERROR(VLOOKUP(VLOOKUP(E8,'Dosis Mx'!$R$55:$X$78,1,FALSE),'Dosis Mx'!$R$55:$X$78,6,FALSE),0) -> 17.5 | AA8: =+F8*(24/H8) -> 240 | AB8: URGENCIAS
A9: 6 | B9: 506-1 | C9: 1034927181 | D9: JULIETA GARCIA RODRIGUEZ | E9: AMIKacina (Sulfato) 500 mg/2 ml Solucion Inyectable | F9: 240 | G9: MG | H9: 24 | I9: H | R9: ALTA, CEFALEXINA 7 DÍAS | S9: N390 | T9: INFECCION DE VIAS URINARIAS, SITIO NO ESPECIFICADO | U9: =+V9*(W9+X9+Y9+Z9) -> 520 | V9: 16 | W9: =IFERROR(VLOOKUP(VLOOKUP(E9,'Dosis Mx'!$R$1:$X$19,1,FALSE),'Dosis Mx'!$R$1:$X$19,6,FALSE),0) -> 15 | X9: =IFERROR(VLOOKUP(VLOOKUP(E9,'Dosis Mx'!$R$20:$X$36,1,FALSE),'Dosis Mx'!$R$20:$X$36,6,FALSE),0) -> 0 | Y9: =IFERROR(VLOOKUP(VLOOKUP(E9,'Dosis Mx'!$R$37:$X$54,1,FALSE),'Dosis Mx'!$R$37:$X$54,6,FALSE),0) -> 0 | Z9: =IFERROR(VLOOKUP(VLOOKUP(E9,'Dosis Mx'!$R$55:$X$78,1,FALSE),'Dosis Mx'!$R$55:$X$78,6,FALSE),0) -> 17.5 | AA9: =+F9*(24/H9) -> 240
A10: 7 | B10: 506-2 | C10: 1039912668 | D10: ANGELESS SOFIA QUINTERO CAMARGO | E10: AMIKacina (Sulfato) 100 mg/2 ml Solucion Inyectable | F10: 147 | G10: MG | H10: 24 | I10: H | J10: I | L10: X | S10: N390 | T10: INFECCION DE VIAS URINARIAS, SITIO NO ESPECIFICADO | U10: =+V10*(W10+X10+Y10+Z10) -> 318.5 | V10: 9.8 | W10: =IFERROR(VLOOKUP(VLOOKUP(E10,'Dosis Mx'!$R$1:$X$19,1,FALSE),'Dosis Mx'!$R$1:$X$19,6,FALSE),0) -> 15 | X10: =IFERROR(VLOOKUP(VLOOKUP(E10,'Dosis Mx'!$R$20:$X$36,1,FALSE),'Dosis Mx'!$R$20:$X$36,6,FALSE),0) -> 0 | Y10: =IFERROR(VLOOKUP(VLOOKUP(E10,'Dosis Mx'!$R$37:$X$54,1,FALSE),'Dosis Mx'!$R$37:$X$54,6,FALSE),0) -> 0 | Z10: =IFERROR(VLOOKUP(VLOOKUP(E10,'Dosis Mx'!$R$55:$X$78,1,FALSE),'Dosis Mx'!$R$55:$X$78,6,FALSE),0) -> 17.5 | AA10: =+F10*(24/H10) -> 147
A11: 8 | B11: Aisl 500 | C11: 1023526248 | D11: MARIANA LOPEZ MUNERA | E11: AMPIcilina Sodica/SULBactam Sodico 1000/500mg Polvo para iny (Ped) | F11: 2000 | G11: MG | H11: 6 | I11: H | J11: NI | L11: X | S11: R509 | T11: FIEBRE, NO ESPECIFICADA | U11: =+V11*(W11+X11+Y11+Z11) -> 9100 | V11: 45.5 | W11: =IFERROR(VLOOKUP(VLOOKUP(E11,'Dosis Mx'!$R$1:$X$19,1,FALSE),'Dosis Mx'!$R$1:$X$19,6,FALSE),0) -> 0 | X11: =IFERROR(VLOOKUP(VLOOKUP(E11,'Dosis Mx'!$R$20:$X$36,1,FALSE),'Dosis Mx'!$R$20:$X$36,6,FALSE),0) -> 0 | Y11: =IFERROR(VLOOKUP(VLOOKUP(E11,'Dosis Mx'!$R$37:$X$54,1,FALSE),'Dosis Mx'!$R$37:$X$54,6,FALSE),0) -> 200 | Z11: =IFERROR(VLOOKUP(VLOOKUP(E11,'Dosis Mx'!$R$55:$X$78,1,FALSE),'Dosis Mx'!$R$55:$X$78,6,FALSE),0) -> 0 | AA11: =+F11*(24/H11) -> 8000
A12: 9 | B12: 708-3 | C12: 1039050469 | D12: JEHILYN HENAO BERMUDEZ | E12: AMIKacina (Sulfato) 100 mg/2 ml Solucion Inyectable | F12: 200 | G12: MG | H12: 24 | I12: H | J12: I | S12: N390 | T12: INFECCION DE VIAS URINARIAS, SITIO NO ESPECIFICADO | U12: =+V12*(W12+X12+Y12+Z12) -> 455 | V12: 14 | W12: =IFERROR(VLOOKUP(VLOOKUP(E12,'Dosis Mx'!$R$1:$X$19,1,FALSE),'Dosis Mx'!$R$1:$X$19,6,FALSE),0) -> 15 | X12: =IFERROR(VLOOKUP(VLOOKUP(E12,'Dosis Mx'!$R$20:$X$36,1,FALSE),'Dosis Mx'!$R$20:$X$36,6,FALSE),0) -> 0 | Y12: =IFERROR(VLOOKUP(VLOOKUP(E12,'Dosis Mx'!$R$37:$X$54,1,FALSE),'Dosis Mx'!$R$37:$X$54,6,FALSE),0) -> 0 | Z12: =IFERROR(VLOOKUP(VLOOKUP(E12,'Dosis Mx'!$R$55:$X$78,1,FALSE),'Dosis Mx'!$R$55:$X$78,6,FALSE),0) -> 17.5 | AA12: =+F12*(24/H12) -> 200
A13: 10 | B13: 708-4 | C13: 1015071491 | D13: MARIA STEFANNY QUINTERO HENAO | E13: Ciprofloxacina (Clorhidrato) 100 mg/10 ml Sln Inyectable | F13: 320 | G13: MG | H13: 8 | I13: H | J13: I | L13: X | S13: N390 | T13: INFECCION DE VIAS URINARIAS, SITIO NO ESPECIFICADO | U13: =+V13*(W13+X13+Y13+Z13) -> 1000 | V13: 40 | W13: =IFERROR(VLOOKUP(VLOOKUP(E13,'Dosis Mx'!$R$1:$X$19,1,FALSE),'Dosis Mx'!$R$1:$X$19,6,FALSE),0) -> 25 | X13: =IFERROR(VLOOKUP(VLOOKUP(E13,'Dosis Mx'!$R$20:$X$36,1,FALSE),'Dosis Mx'!$R$20:$X$36,6,FALSE),0) -> 0 | Y13: =IFERROR(VLOOKUP(VLOOKUP(E13,'Dosis Mx'!$R$37:$X$54,1,FALSE),'Dosis Mx'!$R$37:$X$54,6,FALSE),0) -> 0 | Z13: =IFERROR(VLOOKUP(VLOOKUP(E13,'Dosis Mx'!$R$55:$X$78,1,FALSE),'Dosis Mx'!$R$55:$X$78,6,FALSE),0) -> 0 | AA13: =+F13*(24/H13) -> 960
A14: 11 | B14: 708-6 | C14: 1025677881 | D14: MIA ANDRADES MURILLO | E14: AMIKacina (Sulfato) 500 mg/2 ml Solucion Inyectable | F14: 165 | G14: MG | H14: 24 | I14: H | J14: I | R14: ALTA | S14: N390 | T14: INFECCION DE VIAS URINARIAS, SITIO NO ESPECIFICADO | U14: =+V14*(W14+X14+Y14+Z14) -> 357.5 | V14: 11 | W14: =IFERROR(VLOOKUP(VLOOKUP(E14,'Dosis Mx'!$R$1:$X$19,1,FALSE),'Dosis Mx'!$R$1:$X$19,6,FALSE),0) -> 15 | X14: =IFERROR(VLOOKUP(VLOOKUP(E14,'Dosis Mx'!$R$20:$X$36,1,FALSE),'Dosis Mx'!$R$20:$X$36,6,FALSE),0) -> 0 | Y14: =IFERROR(VLOOKUP(VLOOKUP(E14,'Dosis Mx'!$R$37:$X$54,1,FALSE),'Dosis Mx'!$R$37:$X$54,6,FALSE),0) -> 0 | Z14: =IFERROR(VLOOKUP(VLOOKUP(E14,'Dosis Mx'!$R$55:$X$78,1,FALSE),'Dosis Mx'!$R$55:$X$78,6,FALSE),0) -> 17.5 | AA14: =+F14*(24/H14) -> 165
A15: 12 | B15: 709-1 | C15: 1023665226 | D15: ANTHONY BLANCO GELEZ | E15: AMPIcilina Sodica/SULBactam Sodico 1000/500mg Polvo para iny (Ped) | F15: 400 | G15: MG | H15: 6 | I15: H | J15: I | M15: X | R15: ALTA | S15: A499 | T15: INFECCION BACTERIANA, NO ESPECIFICADA | U15: =+V15*(W15+X15+Y15+Z15) -> 1640 | V15: 8.2 | W15: =IFERROR(VLOOKUP(VLOOKUP(E15,'Dosis Mx'!$R$1:$X$19,1,FALSE),'Dosis Mx'!$R$1:$X$19,6,FALSE),0) -> 0 | X15: =IFERROR(VLOOKUP(VLOOKUP(E15,'Dosis Mx'!$R$20:$X$36,1,FALSE),'Dosis Mx'!$R$20:$X$36,6,FALSE),0) -> 0 | Y15: =IFERROR(VLOOKUP(VLOOKUP(E15,'Dosis Mx'!$R$37:$X$54,1,FALSE),'Dosis Mx'!$R$37:$X$54,6,FALSE),0) -> 200 | Z15: =IFERROR(VLOOKUP(VLOOKUP(E15,'Dosis Mx'!$R$55:$X$78,1,FALSE),'Dosis Mx'!$R$55:$X$78,6,FALSE),0) -> 0 | AA15: =+F15*(24/H15) -> 1600
A16: 13 | B16: 709-4 | C16: 1011420656 | D16: JULIETA MARULANDA RODRIGUEZ | E16: Cefazolina 1000 mg Polvo para Inyeccion | F16: 250 | G16: MG | H16: 6 | I16: H | J16: I | S16: L040 | T16: LINFADENITIS AGUDA DE CARA, CABEZA Y CUELLO | U16: =+V16*(W16+X16+Y16+Z16) -> 980 | V16: 9.8 | W16: =IFERROR(VLOOKUP(VLOOKUP(E16,'Dosis Mx'!$R$1:$X$19,1,FALSE),'Dosis Mx'!$R$1:$X$19,6,FALSE),0) -> 0 | X16: =IFERROR(VLOOKUP(VLOOKUP(E16,'Dosis Mx'!$R$20:$X$36,1,FALSE),'Dosis Mx'!$R$20:$X$36,6,FALSE),0) -> 100 | Y16: =IFERROR(VLOOKUP(VLOOKUP(E16,'Dosis Mx'!$R$37:$X$54,1,FALSE),'Dosis Mx'!$R$37:$X$54,6,FALSE),0) -> 0 | Z16: =IFERROR(VLOOKUP(VLOOKUP(E16,'Dosis Mx'!$R$55:$X$78,1,FALSE),'Dosis Mx'!$R$55:$X$78,6,FALSE),0) -> 0 | AA16: =+F16*(24/H16) -> 1000
A17: 14 | B17: 709-6 | C17: 1078692967 | D17: THARA MARIAM PEÑA ANGULO | E17: Clindamicina (Fosfato) 600 mg /4ml Solucion Inyectable | F17: 160 | G17: MG | H17: 6 | I17: H | J17: I | S17: M255 | T17: DOLOR EN ARTICULACION | U17: =+V17*(W17+X17+Y17+Z17) -> 724.5 | V17: 16.1 | W17: =IFERROR(VLOOKUP(VLOOKUP(E17,'Dosis Mx'!$R$1:$X$19,1,FALSE),'Dosis Mx'!$R$1:$X$19,6,FALSE),0) -> 0 | X17: =IFERROR(VLOOKUP(VLOOKUP(E17,'Dosis Mx'!$R$20:$X$36,1,FALSE),'Dosis Mx'!$R$20:$X$36,6,FALSE),0) -> 10 | Y17: =IFERROR(VLOOKUP(VLOOKUP(E17,'Dosis Mx'!$R$37:$X$54,1,FALSE),'Dosis Mx'!$R$37:$X$54,6,FALSE),0) -> 35 | Z17: =IFERROR(VLOOKUP(VLOOKUP(E17,'Dosis Mx'!$R$55:$X$78,1,FALSE),'Dosis Mx'!$R$55:$X$78,6,FALSE),0) -> 0 | AA17: =+F17*(24/H17) -> 640
A18: 15 | B18: 710-1 | C18: 1023556882 | D18: NICOLAS MONTOYA BEDOYA | E18: AMPIcilina Sodica/SULBactam Sodico 1000/500mg Polvo para iny (Ped) | F18: 800 | G18: MG | H18: 6 | I18: H | J18: I | S18: R509 | T18: FIEBRE, NO ESPECIFICADA | U18: =+V18*(W18+X18+Y18+Z18) -> 3200 | V18: 16 | W18: =IFERROR(VLOOKUP(VLOOKUP(E18,'Dosis Mx'!$R$1:$X$19,1,FALSE),'Dosis Mx'!$R$1:$X$19,6,FALSE),0) -> 0 | X18: =IFERROR(VLOOKUP(VLOOKUP(E18,'Dosis Mx'!$R$20:$X$36,1,FALSE),'Dosis Mx'!$R$20:$X$36,6,FALSE),0) -> 0 | Y18: =IFERROR(VLOOKUP(VLOOKUP(E18,'Dosis Mx'!$R$37:$X$54,1,FALSE),'Dosis Mx'!$R$37:$X$54,6,FALSE),0) -> 200 | Z18: =IFERROR(VLOOKUP(VLOOKUP(E18,'Dosis Mx'!$R$55:$X$78,1,FALSE),'Dosis Mx'!$R$55:$X$78,6,FALSE),0) -> 0 | AA18: =+F18*(24/H18) -> 3200
A19: 16 | B19: 710-5 | C19: 1042095438 | D19: DARIANA MILAGROS YEPES VERGARA | E19: Clindamicina (Fosfato) 600 mg /4ml Solucion Inyectable | F19: 90 | G19: MG | H19: 6 | I19: H | J19: I | S19: L024 | T19: ABSCESO CUTANEO, FURUNCULO Y ANTRAX DE MIEMBRO | U19: =+V19*(W19+X19+Y19+Z19) -> 166.5 | V19: 3.7 | W19: =IFERROR(VLOOKUP(VLOOKUP(E19,'Dosis Mx'!$R$1:$X$19,1,FALSE),'Dosis Mx'!$R$1:$X$19,6,FALSE),0) -> 0 | X19: =IFERROR(VLOOKUP(VLOOKUP(E19,'Dosis Mx'!$R$20:$X$36,1,FALSE),'Dosis Mx'!$R$20:$X$36,6,FALSE),0) -> 10 | Y19: =IFERROR(VLOOKUP(VLOOKUP(E19,'Dosis Mx'!$R$37:$X$54,1,FALSE),'Dosis Mx'!$R$37:$X$54,6,FALSE),0) -> 35 | Z19: =IFERROR(VLOOKUP(VLOOKUP(E19,'Dosis Mx'!$R$55:$X$78,1,FALSE),'Dosis Mx'!$R$55:$X$78,6,FALSE),0) -> 0 | AA19: =+F19*(24/H19) -> 360
A20: 17 | B20: Aisl 701 | C20: 1017284099 | D20: ASHLY JIREH CASTILLO SANCHEZ | E20: AZITromicina200mg/5 ml (4%)Polvo para reconstituirx15ml | F20: 47 | G20: MG | H20: 24 | I20: H | J20: I | S20: R509 | T20: FIEBRE, NO ESPECIFICADA | U20: =+V20*(W20+X20+Y20+Z20) -> 35.25 | V20: 4.7 | W20: =IFERROR(VLOOKUP(VLOOKUP(E20,'Dosis Mx'!$R$1:$X$19,1,FALSE),'Dosis Mx'!$R$1:$X$19,6,FALSE),0) -> 0 | X20: =IFERROR(VLOOKUP(VLOOKUP(E20,'Dosis Mx'!$R$20:$X$36,1,FALSE),'Dosis Mx'!$R$20:$X$36,6,FALSE),0) -> 0 | Y20: =IFERROR(VLOOKUP(VLOOKUP(E20,'Dosis Mx'!$R$37:$X$54,1,FALSE),'Dosis Mx'!$R$37:$X$54,6,FALSE),0) -> 7.5 | Z20: =IFERROR(VLOOKUP(VLOOKUP(E20,'Dosis Mx'!$R$55:$X$78,1,FALSE),'Dosis Mx'!$R$55:$X$78,6,FALSE),0) -> 0 | AA20: =+F20*(24/H20) -> 47
A21: 18 | B21: Aisl 702 | C21: VEN005084 | D21: DIEGO RAFAEL MORALES FLAMEZ | E21: Ceftriaxona (Sal Sodica) 1000 mg Polvo para Inyeccion | F21: 390 | G21: MG | H21: 12 | I21: H | J21: I | S21: N179 | T21: INSUFICIENCIA RENAL AGUDA, NO ESPECIFICADA | U21: =+V21*(W21+X21+Y21+Z21) -> 3372.5 | V21: 7.1 | W21: =IFERROR(VLOOKUP(VLOOKUP(E21,'Dosis Mx'!$R$1:$X$19,1,FALSE),'Dosis Mx'!$R$1:$X$19,6,FALSE),0) -> 300 | X21: =IFERROR(VLOOKUP(VLOOKUP(E21,'Dosis Mx'!$R$20:$X$36,1,FALSE),'Dosis Mx'!$R$20:$X$36,6,FALSE),0) -> 0 | Y21: =IFERROR(VLOOKUP(VLOOKUP(E21,'Dosis Mx'!$R$37:$X$54,1,FALSE),'Dosis Mx'!$R$37:$X$54,6,FALSE),0) -> 75 | Z21: =IFERROR(VLOOKUP(VLOOKUP(E21,'Dosis Mx'!$R$55:$X$78,1,FALSE),'Dosis Mx'!$R$55:$X$78,6,FALSE),0) -> 100 | AA21: =+F21*(24/H21) -> 780
A22: 19 | B22: Aisl 703 | C22: 1011420925 | D22: ALAN CAMILO MUÑOZ ZAPATA | E22: AMPIcilina Sodica/SULBactam Sodico 1000/500mg Polvo para iny (Ped) | F22: 450 | G22: MG | H22: 6 | I22: H | J22: I | S22: J219 | T22: BRONQUIOLITIS AGUDA, NO ESPECIFICADA | U22: =+V22*(W22+X22+Y22+Z22) -> 1700 | V22: 8.5 | W22: =IFERROR(VLOOKUP(VLOOKUP(E22,'Dosis Mx'!$R$1:$X$19,1,FALSE),'Dosis Mx'!$R$1:$X$19,6,FALSE),0) -> 0 | X22: =IFERROR(VLOOKUP(VLOOKUP(E22,'Dosis Mx'!$R$20:$X$36,1,FALSE),'Dosis Mx'!$R$20:$X$36,6,FALSE),0) -> 0 | Y22: =IFERROR(VLOOKUP(VLOOKUP(E22,'Dosis Mx'!$R$37:$X$54,1,FALSE),'Dosis Mx'!$R$37:$X$54,6,FALSE),0) -> 200 | Z22: =IFERROR(VLOOKUP(VLOOKUP(E22,'Dosis Mx'!$R$55:$X$78,1,FALSE),'Dosis Mx'!$R$55:$X$78,6,FALSE),0) -> 0 | AA22: =+F22*(24/H22) -> 1800
A23: 20 | B23: Aisl 705 | C23: 1031948923 | D23: MATEO VALENCIA VASQUEZ | E23: Ciprofloxacina (Clorhidrato) 100 mg/10 ml Sln Inyectable | F23: 90 | G23: MG | H23: 12 | I23: H | J23: I | L23: X | S23: A090 | T23: OTRAS GASTROENTERITIS Y COLITIS DE ORIGEN INFECCIOSO | U23: =+V23*(W23+X23+Y23+Z23) -> 225 | V23: 9 | W23: =IFERROR(VLOOKUP(VLOOKUP(E23,'Dosis Mx'!$R$1:$X$19,1,FALSE),'Dosis Mx'!$R$1:$X$19,6,FALSE),0) -> 25 | X23: =IFERROR(VLOOKUP(VLOOKUP(E23,'Dosis Mx'!$R$20:$X$36,1,FALSE),'Dosis Mx'!$R$20:$X$36,6,FALSE),0) -> 0 | Y23: =IFERROR(VLOOKUP(VLOOKUP(E23,'Dosis Mx'!$R$37:$X$54,1,FALSE),'Dosis Mx'!$R$37:$X$54,6,FALSE),0) -> 0 | Z23: =IFERROR(VLOOKUP(VLOOKUP(E23,'Dosis Mx'!$R$55:$X$78,1,FALSE),'Dosis Mx'!$R$55:$X$78,6,FALSE),0) -> 0 | AA23: =+F23*(24/H23) -> 180
A24: 21 | B24: Aisl 706 | C24: 1040262325 | D24: VICTOR ALFONSO FLOREZ AGUDELO | E24: Fluconazol 50 mg/5 ml Polvo para Suspension Frasco X 20 ml | F24: 85 | G24: MG | H24: 24 | I24: H | J24: I | R24: PROFILACTICO | S24: L080 | T24: PIODERMA | U24: =+V24*(W24+X24+Y24+Z24) -> 0 | V24: 6.55 | W24: =IFERROR(VLOOKUP(VLOOKUP(E24,'Dosis Mx'!$R$1:$X$19,1,FALSE),'Dosis Mx'!$R$1:$X$19,6,FALSE),0) -> 0 | X24: =IFERROR(VLOOKUP(VLOOKUP(E24,'Dosis Mx'!$R$20:$X$36,1,FALSE),'Dosis Mx'!$R$20:$X$36,6,FALSE),0) -> 0 | Y24: =IFERROR(VLOOKUP(VLOOKUP(E24,'Dosis Mx'!$R$37:$X$54,1,FALSE),'Dosis Mx'!$R$37:$X$54,6,FALSE),0) -> 0 | Z24: =IFERROR(VLOOKUP(VLOOKUP(E24,'Dosis Mx'!$R$55:$X$78,1,FALSE),'Dosis Mx'!$R$55:$X$78,6,FALSE),0) -> 0 | AA24: =+F24*(24/H24) -> 85
A25: 22 | B25: Aisl 707 | C25: 23099110655662 | D25: HIJO DE EMILSE PAOLA OSORIO | E25: Oxacilina (Sal Sodica) 1000 mg Polvo para Inyeccion | F25: 135 | G25: MG | H25: 6 | I25: H | R25: ALTA | S25: L032 | T25: CELULITIS DE LA CARA | U25: =+V25*(W25+X25+Y25+Z25) -> 1080 | V25: 2.7 | W25: =IFERROR(VLOOKUP(VLOOKUP(E25,'Dosis Mx'!$R$1:$X$19,1,FALSE),'Dosis Mx'!$R$1:$X$19,6,FALSE),0) -> 0 | X25: =IFERROR(VLOOKUP(VLOOKUP(E25,'Dosis Mx'!$R$20:$X$36,1,FALSE),'Dosis Mx'!$R$20:$X$36,6,FALSE),0) -> 200 | Y25: =IFERROR(VLOOKUP(VLOOKUP(E25,'Dosis Mx'!$R$37:$X$54,1,FALSE),'Dosis Mx'!$R$37:$X$54,6,FALSE),0) -> 0 | Z25: =IFERROR(VLOOKUP(VLOOKUP(E25,'Dosis Mx'!$R$55:$X$78,1,FALSE),'Dosis Mx'!$R$55:$X$78,6,FALSE),0) -> 200 | AA25: =+F25*(24/H25) -> 540
A26: 23 | U26: =+V26*(W26+X26+Y26+Z26) -> 0 | W26: =IFERROR(VLOOKUP(VLOOKUP(E26,'Dosis Mx'!$R$1:$X$19,1,FALSE),'Dosis Mx'!$R$1:$X$19,6,FALSE),0) -> 0 | X26: =IFERROR(VLOOKUP(VLOOKUP(E26,'Dosis Mx'!$R$20:$X$36,1,FALSE),'Dosis Mx'!$R$20:$X$36,6,FALSE),0) -> 0 | Y26: =IFERROR(VLOOKUP(VLOOKUP(E26,'Dosis Mx'!$R$37:$X$54,1,FALSE),'Dosis Mx'!$R$37:$X$54,6,FALSE),0) -> 0 | Z26: =IFERROR(VLOOKUP(VLOOKUP(E26,'Dosis Mx'!$R$55:$X$78,1,FALSE),'Dosis Mx'!$R$55:$X$78,6,FALSE),0) -> 0 | AA26: =+F26*(24/H26) -> #DIV/0!
A27: 24 | U27: =+V27*(W27+X27+Y27+Z27) -> 0 | W27: =IFERROR(VLOOKUP(VLOOKUP(E27,'Dosis Mx'!$R$1:$X$19,1,FALSE),'Dosis Mx'!$R$1:$X$19,6,FALSE),0) -> 0 | X27: =IFERROR(VLOOKUP(VLOOKUP(E27,'Dosis Mx'!$R$20:$X$36,1,FALSE),'Dosis Mx'!$R$20:$X$36,6,FALSE),0) -> 0 | Y27: =IFERROR(VLOOKUP(VLOOKUP(E27,'Dosis Mx'!$R$37:$X$54,1,FALSE),'Dosis Mx'!$R$37:$X$54,6,FALSE),0) -> 0 | Z27: =IFERROR(VLOOKUP(VLOOKUP(E27,'Dosis Mx'!$R$55:$X$78,1,FALSE),'Dosis Mx'!$R$55:$X$78,6,FALSE),0) -> 0 | AA27: =+F27*(24/H27) -> #DIV/0!
A28: 25 | U28: =+V28*(W28+X28+Y28+Z28) -> 0 | W28: =IFERROR(VLOOKUP(VLOOKUP(E28,'Dosis Mx'!$R$1:$X$19,1,FALSE),'Dosis Mx'!$R$1:$X$19,6,FALSE),0) -> 0 | X28: =IFERROR(VLOOKUP(VLOOKUP(E28,'Dosis Mx'!$R$20:$X$36,1,FALSE),'Dosis Mx'!$R$20:$X$36,6,FALSE),0) -> 0 | Y28: =IFERROR(VLOOKUP(VLOOKUP(E28,'Dosis Mx'!$R$37:$X$54,1,FALSE),'Dosis Mx'!$R$37:$X$54,6,FALSE),0) -> 0 | Z28: =IFERROR(VLOOKUP(VLOOKUP(E28,'Dosis Mx'!$R$55:$X$78,1,FALSE),'Dosis Mx'!$R$55:$X$78,6,FALSE),0) -> 0 | AA28: =+F28*(24/H28) -> #DIV/0!
A29: 26 | U29: =+V29*(W29+X29+Y29+Z29) -> 0 | W29: =IFERROR(VLOOKUP(VLOOKUP(E29,'Dosis Mx'!$R$1:$X$19,1,FALSE),'Dosis Mx'!$R$1:$X$19,6,FALSE),0) -> 0 | X29: =IFERROR(VLOOKUP(VLOOKUP(E29,'Dosis Mx'!$R$20:$X$36,1,FALSE),'Dosis Mx'!$R$20:$X$36,6,FALSE),0) -> 0 | Y29: =IFERROR(VLOOKUP(VLOOKUP(E29,'Dosis Mx'!$R$37:$X$54,1,FALSE),'Dosis Mx'!$R$37:$X$54,6,FALSE),0) -> 0 | Z29: =IFERROR(VLOOKUP(VLOOKUP(E29,'Dosis Mx'!$R$55:$X$78,1,FALSE),'Dosis Mx'!$R$55:$X$78,6,FALSE),0) -> 0 | AA29: =+F29*(24/H29) -> #DIV/0!
A30: 27 | U30: =+V30*(W30+X30+Y30+Z30) -> 0 | W30: =IFERROR(VLOOKUP(VLOOKUP(E30,'Dosis Mx'!$R$1:$X$19,1,FALSE),'Dosis Mx'!$R$1:$X$19,6,FALSE),0) -> 0 | X30: =IFERROR(VLOOKUP(VLOOKUP(E30,'Dosis Mx'!$R$20:$X$36,1,FALSE),'Dosis Mx'!$R$20:$X$36,6,FALSE),0) -> 0 | Y30: =IFERROR(VLOOKUP(VLOOKUP(E30,'Dosis Mx'!$R$37:$X$54,1,FALSE),'Dosis Mx'!$R$37:$X$54,6,FALSE),0) -> 0 | Z30: =IFERROR(VLOOKUP(VLOOKUP(E30,'Dosis Mx'!$R$55:$X$78,1,FALSE),'Dosis Mx'!$R$55:$X$78,6,FALSE),0) -> 0 | AA30: =+F30*(24/H30) -> #DIV/0!
A31: 28 | U31: =+V31*(W31+X31+Y31+Z31) -> 0 | W31: =IFERROR(VLOOKUP(VLOOKUP(E31,'Dosis Mx'!$R$1:$X$19,1,FALSE),'Dosis Mx'!$R$1:$X$19,6,FALSE),0) -> 0 | X31: =IFERROR(VLOOKUP(VLOOKUP(E31,'Dosis Mx'!$R$20:$X$36,1,FALSE),'Dosis Mx'!$R$20:$X$36,6,FALSE),0) -> 0 | Y31: =IFERROR(VLOOKUP(VLOOKUP(E31,'Dosis Mx'!$R$37:$X$54,1,FALSE),'Dosis Mx'!$R$37:$X$54,6,FALSE),0) -> 0 | Z31: =IFERROR(VLOOKUP(VLOOKUP(E31,'Dosis Mx'!$R$55:$X$78,1,FALSE),'Dosis Mx'!$R$55:$X$78,6,FALSE),0) -> 0 | AA31: =+F31*(24/H31) -> #DIV/0!
A32: 29 | U32: =+V32*(W32+X32+Y32+Z32) -> 0 | W32: =IFERROR(VLOOKUP(VLOOKUP(E32,'Dosis Mx'!$R$1:$X$19,1,FALSE),'Dosis Mx'!$R$1:$X$19,6,FALSE),0) -> 0 | X32: =IFERROR(VLOOKUP(VLOOKUP(E32,'Dosis Mx'!$R$20:$X$36,1,FALSE),'Dosis Mx'!$R$20:$X$36,6,FALSE),0) -> 0 | Y32: =IFERROR(VLOOKUP(VLOOKUP(E32,'Dosis Mx'!$R$37:$X$54,1,FALSE),'Dosis Mx'!$R$37:$X$54,6,FALSE),0) -> 0 | Z32: =IFERROR(VLOOKUP(VLOOKUP(E32,'Dosis Mx'!$R$55:$X$78,1,FALSE),'Dosis Mx'!$R$55:$X$78,6,FALSE),0) -> 0 | AA32: =+F32*(24/H32) -> #DIV/0!
A33: No | B33: Servicio | E33: Nombre | F33: Dosis | G33: Medidadosis | H33: Frecuencia | I33: Unidadfrecuencia | J33: Tto Empirico | K33: Tto Dirigido | L33: cultivo | M33: Suspender | N33: Cambiar | R33: Observacionesorden | S33: Codigo Diagnostico | T33: Diagnostico | U33: Dosis | V33: Peso(kg) | W33: ITU | X33: ITB | Y33: NEUMONIA | Z33: MENINGITIS | AA33: Dosis recetada
N34: Escalar | O34: Desescalar | P34: RXN adversa | Q34: Por dosis
U35: =+V35*(W35+X35+Y35+Z35) -> 0 | W35: =IFERROR(VLOOKUP(VLOOKUP(E35,'Dosis Mx'!$R$1:$X$19,1,FALSE),'Dosis Mx'!$R$1:$X$19,6,FALSE),0) -> 0 | X35: =IFERROR(VLOOKUP(VLOOKUP(E35,'Dosis Mx'!$R$20:$X$36,1,FALSE),'Dosis Mx'!$R$20:$X$36,6,FALSE),0) -> 0 | Y35: =IFERROR(VLOOKUP(VLOOKUP(E35,'Dosis Mx'!$R$37:$X$54,1,FALSE),'Dosis Mx'!$R$37:$X$54,6,FALSE),0) -> 0 | Z35: =IFERROR(VLOOKUP(VLOOKUP(E35,'Dosis Mx'!$R$55:$X$78,1,FALSE),'Dosis Mx'!$R$55:$X$78,6,FALSE),0) -> 0 | AA35: =+F35*(24/H35) -> #DIV/0!
U36: =+V36*(W36+X36+Y36+Z36) -> 0 | W36: =IFERROR(VLOOKUP(VLOOKUP(E36,'Dosis Mx'!$R$1:$X$19,1,FALSE),'Dosis Mx'!$R$1:$X$19,6,FALSE),0) -> 0 | X36: =IFERROR(VLOOKUP(VLOOKUP(E36,'Dosis Mx'!$R$20:$X$36,1,FALSE),'Dosis Mx'!$R$20:$X$36,6,FALSE),0) -> 0 | Y36: =IFERROR(VLOOKUP(VLOOKUP(E36,'Dosis Mx'!$R$37:$X$54,1,FALSE),'Dosis Mx'!$R$37:$X$54,6,FALSE),0) -> 0 | Z36: =IFERROR(VLOOKUP(VLOOKUP(E36,'Dosis Mx'!$R$55:$X$78,1,FALSE),'Dosis Mx'!$R$55:$X$78,6,FALSE),0) -> 0 | AA36: =+F36*(24/H36) -> #DIV/0!
U37: =+V37*(W37+X37+Y37+Z37) -> 0 | W37: =IFERROR(VLOOKUP(VLOOKUP(E37,'Dosis Mx'!$R$1:$X$19,1,FALSE),'Dosis Mx'!$R$1:$X$19,6,FALSE),0) -> 0 | X37: =IFERROR(VLOOKUP(VLOOKUP(E37,'Dosis Mx'!$R$20:$X$36,1,FALSE),'Dosis Mx'!$R$20:$X$36,6,FALSE),0) -> 0 | Y37: =IFERROR(VLOOKUP(VLOOKUP(E37,'Dosis Mx'!$R$37:$X$54,1,FALSE),'Dosis Mx'!$R$37:$X$54,6,FALSE),0) -> 0 | Z37: =IFERROR(VLOOKUP(VLOOKUP(E37,'Dosis Mx'!$R$55:$X$78,1,FALSE),'Dosis Mx'!$R$55:$X$78,6,FALSE),0) -> 0 | AA37: =+F37*(24/H37) -> #DIV/0!
U38: =+V38*(W38+X38+Y38+Z38) -> 0 | W38: =IFERROR(VLOOKUP(VLOOKUP(E38,'Dosis Mx'!$R$1:$X$19,1,FALSE),'Dosis Mx'!$R$1:$X$19,6,FALSE),0) -> 0 | X38: =IFERROR(VLOOKUP(VLOOKUP(E38,'Dosis Mx'!$R$20:$X$36,1,FALSE),'Dosis Mx'!$R$20:$X$36,6,FALSE),0) -> 0 | Y38: =IFERROR(VLOOKUP(VLOOKUP(E38,'Dosis Mx'!$R$37:$X$54,1,FALSE),'Dosis Mx'!$R$37:$X$54,6,FALSE),0) -> 0 | Z38: =IFERROR(VLOOKUP(VLOOKUP(E38,'Dosis Mx'!$R$55:$X$78,1,FALSE),'Dosis Mx'!$R$55:$X$78,6,FALSE),0) -> 0 | AA38: =+F38*(24/H38) -> #DIV/0!
U39: =+V39*(W39+X39+Y39+Z39) -> 0 | W39: =IFERROR(VLOOKUP(VLOOKUP(E39,'Dosis Mx'!$R$1:$X$19,1,FALSE),'Dosis Mx'!$R$1:$X$19,6,FALSE),0) -> 0 | X39: =IFERROR(VLOOKUP(VLOOKUP(E39,'Dosis Mx'!$R$20:$X$36,1,FALSE),'Dosis Mx'!$R$20:$X$36,6,FALSE),0) -> 0 | Y39: =IFERROR(VLOOKUP(VLOOKUP(E39,'Dosis Mx'!$R$37:$X$54,1,FALSE),'Dosis Mx'!$R$37:$X$54,6,FALSE),0) -> 0 | Z39: =IFERROR(VLOOKUP(VLOOKUP(E39,'Dosis Mx'!$R$55:$X$78,1,FALSE),'Dosis Mx'!$R$55:$X$78,6,FALSE),0) -> 0 | AA39: =+F39*(24/H39) -> #DIV/0!
U40: =+V40*(W40+X40+Y40+Z40) -> 0 | W40: =IFERROR(VLOOKUP(VLOOKUP(E40,'Dosis Mx'!$R$1:$X$19,1,FALSE),'Dosis Mx'!$R$1:$X$19,6,FALSE),0) -> 0 | X40: =IFERROR(VLOOKUP(VLOOKUP(E40,'Dosis Mx'!$R$20:$X$36,1,FALSE),'Dosis Mx'!$R$20:$X$36,6,FALSE),0) -> 0 | Y40: =IFERROR(VLOOKUP(VLOOKUP(E40,'Dosis Mx'!$R$37:$X$54,1,FALSE),'Dosis Mx'!$R$37:$X$54,6,FALSE),0) -> 0 | Z40: =IFERROR(VLOOKUP(VLOOKUP(E40,'Dosis Mx'!$R$55:$X$78,1,FALSE),'Dosis Mx'!$R$55:$X$78,6,FALSE),0) -> 0 | AA40: =+F40*(24/H40) -> #DIV/0!
...

Sheet 17-10-2023
B1: FECHA | C1: 45216
A2: No | B2: Servicio | C2: Docidentidad | D2: Usuario | E2: Nombre | F2: Dosis | G2: Medidadosis | H2: Frecuencia | I2: Unidadfrecuencia | J2: Tto Empirico | K2: Tto Dirigido | L2: cultivo | M2: Suspender | N2: Cambiar | R2: Observacionesorden | S2: Codigo Diagnostico | T2: Diagnostico | U2: Dosis | V2: Peso(kg) | W2: ITU | X2: ITB | Y2: NEUMONIA | Z2: MENINGITIS | AA2: Dosis recetada
N3: Escalar | O3: Desescalar | P3: RXN adversa | Q3: Por dosis
A4: 1 | B4: 601-3 | C4: 1023547489 | D4: MARIANTONIA BURITICA RESTREPO | E4: AMPIcilina (Sal Sodica) x 1000 mg Polvo para Inyeccion | F4: 850 | G4: MG | H4: 6 | I4: H | S4: E86X | T4: DEPLECION DEL VOLUMEN | U4: =+V4*(W4+X4+Y4+Z4) -> 8010 | V4: 17.8 | W4: =IFERROR(VLOOKUP(VLOOKUP(E4,'Dosis Mx'!$R$1:$X$19,1,FALSE),'Dosis Mx'!$R$1:$X$19,6,FALSE),0) -> 0 | X4: =IFERROR(VLOOKUP(VLOOKUP(E4,'Dosis Mx'!$R$20:$X$36,1,FALSE),'Dosis Mx'!$R$20:$X$36,6,FALSE),0) -> 0 | Y4: =IFERROR(VLOOKUP(VLOOKUP(E4,'Dosis Mx'!$R$37:$X$54,1,FALSE),'Dosis Mx'!$R$37:$X$54,6,FALSE),0) -> 200 | Z4: =IFERROR(VLOOKUP(VLOOKUP(E4,'Dosis Mx'!$R$55:$X$78,1,FALSE),'Dosis Mx'!$R$55:$X$78,6,FALSE),0) -> 250 | AA4: =+F4*(24/H4) -> 3400 | AB4: 5
A5: 2 | B5: 601-6 | C5: 1037676780 | D5: MARIA ANTONIA HENAO FONNEGRA | E5: Ceftriaxona (Sal Sodica) 1000 mg Polvo para Inyeccion | F5: 180 | G5: MG | H5: 12 | I5: H | S5: J219 | T5: BRONQUIOLITIS AGUDA, NO ESPECIFICADA | U5: =+V5*(W5+X5+Y5+Z5) -> 1425 | V5: 3 | W5: =IFERROR(VLOOKUP(VLOOKUP(E5,'Dosis Mx'!$R$1:$X$19,1,FALSE),'Dosis Mx'!$R$1:$X$19,6,FALSE),0) -> 300 | X5: =IFERROR(VLOOKUP(VLOOKUP(E5,'Dosis Mx'!$R$20:$X$36,1,FALSE),'Dosis Mx'!$R$20:$X$36,6,FALSE),0) -> 0 | Y5: =IFERROR(VLOOKUP(VLOOKUP(E5,'Dosis Mx'!$R$37:$X$54,1,FALSE),'Dosis Mx'!$R$37:$X$54,6,FALSE),0) -> 75 | Z5: =IFERROR(VLOOKUP(VLOOKUP(E5,'Dosis Mx'!$R$55:$X$78,1,FALSE),'Dosis Mx'!$R$55:$X$78,6,FALSE),0) -> 100 | AA5: =+F5*(24/H5) -> 360 | AB5: 6
A6: 3 | B6: 602-1 | C6: 1037505755 | D6: MARIANGEL SOSA ISAZA | E6: AMPIcilina (Sal Sodica) x 1000 mg Polvo para Inyeccion | F6: 390 | G6: MG | H6: 6 | I6: H | S6: J159 | T6: NEUMONIA BACTERIANA, NO ESPECIFICADA | U6: =+V6*(W6+X6+Y6+Z6) -> 3510 | V6: 7.8 | W6: =IFERROR(VLOOKUP(VLOOKUP(E6,'Dosis Mx'!$R$1:$X$19,1,FALSE),'Dosis Mx'!$R$1:$X$19,6,FALSE),0) -> 0 | X6: =IFERROR(VLOOKUP(VLOOKUP(E6,'Dosis Mx'!$R$20:$X$36,1,FALSE),'Dosis Mx'!$R$20:$X$36,6,FALSE),0) -> 0 | Y6: =IFERROR(VLOOKUP(VLOOKUP(E6,'Dosis Mx'!$R$37:$X$54,1,FALSE),'Dosis Mx'!$R$37:$X$54,6,FALSE),0) -> 200 | Z6: =IFERROR(VLOOKUP(VLOOKUP(E6,'Dosis Mx'!$R$55:$X$78,1,FALSE),'Dosis Mx'!$R$55:$X$78,6,FALSE),0) -> 250 | AA6: =+F6*(24/H6) -> 1560 | AB6: 7
A7: 4 | B7: 603-5 | C7: 1038145231 | D7: MARTIN ALEJANDRO LONDOÑO JARAMILLO | E7: Clindamicina (Fosfato) 600 mg /4ml Solucion Inyectable | F7: 160 | G7: MG | H7: 6 | I7: H | S7: R599 | T7: ADENOMEGALIA, NO ESPECIFICADA | U7: =+V7*(W7+X7+Y7+Z7) -> 720 | V7: 16 | W7: =IFERROR(VLOOKUP(VLOOKUP(E7,'Dosis Mx'!$R$1:$X$19,1,FALSE),'Dosis Mx'!$R$1:$X$19,6,FALSE),0) -> 0 | X7: =IFERROR(VLOOKUP(VLOOKUP(E7,'Dosis Mx'!$R$20:$X$36,1,FALSE),'Dosis Mx'!$R$20:$X$36,6,FALSE),0) -> 10 | Y7: =IFERROR(VLOOKUP(VLOOKUP(E7,'Dosis Mx'!$R$37:$X$54,1,FALSE),'Dosis Mx'!$R$37:$X$54,6,FALSE),0) -> 35 | Z7: =IFERROR(VLOOKUP(VLOOKUP(E7,'Dosis Mx'!$R$55:$X$78,1,FALSE),'Dosis Mx'!$R$55:$X$78,6,FALSE),0) -> 0 | AA7: =+F7*(24/H7) -> 640 | AB7: UCI
A8: 5 | B8: 604-4 | C8: 1027815922 | D8: ASHLEY MEDINA VINASCO | E8: AZITromicina200mg/5 ml (4%)Polvo para reconstituirx15ml | F8: 110 | G8: MG | H8: 24 | I8: H | S8: J129 | T8: NEUMONIA VIRAL, NO ESPECIFICADA | U8: =+V8*(W8+X8+Y8+Z8) -> 82.5 | V8: 11 | W8: =IFERROR(VLOOKUP(VLOOKUP(E8,'Dosis Mx'!$R$1:$X$19,1,FALSE),'Dosis Mx'!$R$1:$X$19,6,FALSE),0) -> 0 | X8: =IFERROR(VLOOKUP(VLOOKUP(E8,'Dosis Mx'!$R$20:$X$36,1,FALSE),'Dosis Mx'!$R$20:$X$36,6,FALSE),0) -> 0 | Y8: =IFERROR(VLOOKUP(VLOOKUP(E8,'Dosis Mx'!$R$37:$X$54,1,FALSE),'Dosis Mx'!$R$37:$X$54,6,FALSE),0) -> 7.5 | Z8: =IFERROR(VLOOKUP(VLOOKUP(E8,'Dosis Mx'!$R$55:$X$78,1,FALSE),'Dosis Mx'!$R$55:$X$78,6,FALSE),0) -> 0 | AA8: =+F8*(24/H8) -> 110 | AB8: URGENCIAS
A9: 6 | B9: 606-1 | C9: 1077652699 | D9: HEINNI KARINA CHAMARRA OBISPO | E9: AMPIcilina Sodica/SULBactam Sodico 1000/500mg Polvo para iny (Ped) | F9: 250 | G9: MG | H9: 6 | I9: H | S9: Q250 | T9: CONDUCTO ARTERIOSO PERSISTENTE | U9: =+V9*(W9+X9+Y9+Z9) -> 1040 | V9: 5.2 | W9: =IFERROR(VLOOKUP(VLOOKUP(E9,'Dosis Mx'!$R$1:$X$19,1,FALSE),'Dosis Mx'!$R$1:$X$19,6,FALSE),0) -> 0 | X9: =IFERROR(VLOOKUP(VLOOKUP(E9,'Dosis Mx'!$R$20:$X$36,1,FALSE),'Dosis Mx'!$R$20:$X$36,6,FALSE),0) -> 0 | Y9: =IFERROR(VLOOKUP(VLOOKUP(E9,'Dosis Mx'!$R$37:$X$54,1,FALSE),'Dosis Mx'!$R$37:$X$54,6,FALSE),0) -> 200 | Z9: =IFERROR(VLOOKUP(VLOOKUP(E9,'Dosis Mx'!$R$55:$X$78,1,FALSE),'Dosis Mx'!$R$55:$X$78,6,FALSE),0) -> 0 | AA9: =+F9*(24/H9) -> 1000
A10: 7 | B10: 606-2 | C10: 1013370693 | D10: JERONIMO VELEZ ARENAS | E10: AMPIcilina Sodica/SULBactam Sodico 1000/500mg Polvo para iny (Ped) | F10: 1000 | G10: MG | H10: 6 | I10: H | S10: J22X | T10: INFECCION AGUDA NO ESPECIFICADA DE LAS VIAS RESPIRATORIAS INFERIORES | U10: =+V10*(W10+X10+Y10+Z10) -> 3560 | V10: 17.8 | W10: =IFERROR(VLOOKUP(VLOOKUP(E10,'Dosis Mx'!$R$1:$X$19,1,FALSE),'Dosis Mx'!$R$1:$X$19,6,FALSE),0) -> 0 | X10: =IFERROR(VLOOKUP(VLOOKUP(E10,'Dosis Mx'!$R$20:$X$36,1,FALSE),'Dosis Mx'!$R$20:$X$36,6,FALSE),0) -> 0 | Y10: =IFERROR(VLOOKUP(VLOOKUP(E10,'Dosis Mx'!$R$37:$X$54,1,FALSE),'Dosis Mx'!$R$37:$X$54,6,FALSE),0) -> 200 | Z10: =IFERROR(VLOOKUP(VLOOKUP(E10,'Dosis Mx'!$R$55:$X$78,1,FALSE),'Dosis Mx'!$R$55:$X$78,6,FALSE),0) -> 0 | AA10: =+F10*(24/H10) -> 4000
A11: 8 | B11: Obs 10 | C11: 1033206498 | D11: ALAN ZAID CORREA ECHEVERRY | E11: AMPIcilina Sodica/SULBactam Sodico 1000/500mg Polvo para iny (Ped) | F11: 900 | G11: MG | H11: 6 | I11: H | S11: J459 | T11: ASMA, NO ESPECIFICADO | U11: =+V11*(W11+X11+Y11+Z11) -> 2400 | V11: 12 | W11: =IFERROR(VLOOKUP(VLOOKUP(E11,'Dosis Mx'!$R$1:$X$19,1,FALSE),'Dosis Mx'!$R$1:$X$19,6,FALSE),0) -> 0 | X11: =IFERROR(VLOOKUP(VLOOKUP(E11,'Dosis Mx'!$R$20:$X$36,1,FALSE),'Dosis Mx'!$R$20:$X$36,6,FALSE),0) -> 0 | Y11: =IFERROR(VLOOKUP(VLOOKUP(E11,'Dosis Mx'!$R$37:$X$54,1,FALSE),'Dosis Mx'!$R$37:$X$54,6,FALSE),0) -> 200 | Z11: =IFERROR(VLOOKUP(VLOOKUP(E11,'Dosis Mx'!$R$55:$X$78,1,FALSE),'Dosis Mx'!$R$55:$X$78,6,FALSE),0) -> 0 | AA11: =+F11*(24/H11) -> 3600
A12: 9 | B12: S2 Silla 4 | C12: 1023662936 | D12: EMILIANO CARDONA MONTES | E12: AMPIcilina 500 mg Polvo para Inyeccion | F12: 490 | G12: MG | H12: 6 | I12: H | S12: H650 | T12: OTITIS MEDIA AGUDA SEROSA | U12: =+V12*(W12+X12+Y12+Z12) -> 4770 | V12: 10.6 | W12: =IFERROR(VLOOKUP(VLOOKUP(E12,'Dosis Mx'!$R$1:$X$19,1,FALSE),'Dosis Mx'!$R$1:$X$19,6,FALSE),0) -> 0 | X12: =IFERROR(VLOOKUP(VLOOKUP(E12,'Dosis Mx'!$R$20:$X$36,1,FALSE),'Dosis Mx'!$R$20:$X$36,6,FALSE),0) -> 0 | Y12: =IFERROR(VLOOKUP(VLOOKUP(E12,'Dosis Mx'!$R$37:$X$54,1,FALSE),'Dosis Mx'!$R$37:$X$54,6,FALSE),0) -> 200 | Z12: =IFERROR(VLOOKUP(VLOOKUP(E12,'Dosis Mx'!$R$55:$X$78,1,FALSE),'Dosis Mx'!$R$55:$X$78,6,FALSE),0) -> 250 | AA12: =+F12*(24/H12) -> 1960
A13: 10 | B13: S3 Silla12 | C13: 1017255324 | D13: SAMANTHA VALENTINA CARMONA GARCIA | E13: Cefazolina 1000 mg Polvo para Inyeccion | F13: 700 | G13: MG | H13: 8 | I13: H | S13: S925 | T13: FRACTURA DE LOS HUESOS DE OTRO(S) DEDO(S) DEL PIE | U13: =+V13*(W13+X13+Y13+Z13) -> 2700 | V13: 27 | W13: =IFERROR(VLOOKUP(VLOOKUP(E13,'Dosis Mx'!$R$1:$X$19,1,FALSE),'Dosis Mx'!$R$1:$X$19,6,FALSE),0) -> 0 | X13: =IFERROR(VLOOKUP(VLOOKUP(E13,'Dosis Mx'!$R$20:$X$36,1,FALSE),'Dosis Mx'!$R$20:$X$36,6,FALSE),0) -> 100 | Y13: =IFERROR(VLOOKUP(VLOOKUP(E13,'Dosis Mx'!$R$37:$X$54,1,FALSE),'Dosis Mx'!$R$37:$X$54,6,FALSE),0) -> 0 | Z13: =IFERROR(VLOOKUP(VLOOKUP(E13,'Dosis Mx'!$R$55:$X$78,1,FALSE),'Dosis Mx'!$R$55:$X$78,6,FALSE),0) -> 0 | AA13: =+F13*(24/H13) -> 2100
A14: 11 | B14: UCE 02 | C14: 1032027895 | D14: JUAN ANDRES PATIÑO ROLDAN | E14: AZITromicina 500 mg Tableta | F14: 500 | G14: MG | H14: 24 | I14: H | S14: J46X | T14: ESTADO ASMATICO | U14: =+V14*(W14+X14+Y14+Z14) -> 412.5 | V14: 55 | W14: =IFERROR(VLOOKUP(VLOOKUP(E14,'Dosis Mx'!$R$1:$X$19,1,FALSE),'Dosis Mx'!$R$1:$X$19,6,FALSE),0) -> 0 | X14: =IFERROR(VLOOKUP(VLOOKUP(E14,'Dosis Mx'!$R$20:$X$36,1,FALSE),'Dosis Mx'!$R$20:$X$36,6,FALSE),0) -> 0 | Y14: =IFERROR(VLOOKUP(VLOOKUP(E14,'Dosis Mx'!$R$37:$X$54,1,FALSE),'Dosis Mx'!$R$37:$X$54,6,FALSE),0) -> 7.5 | Z14: =IFERROR(VLOOKUP(VLOOKUP(E14,'Dosis Mx'!$R$55:$X$78,1,FALSE),'Dosis Mx'!$R$55:$X$78,6,FALSE),0) -> 0 | AA14: =+F14*(24/H14) -> 500
A15: 12 | B15: UCE 04 | C15: 1037138346 | D15: ISABELLA MANCO LUNA | E15: Cefepime 1000 mg Polvo para inyeccion | F15: 150 | G15: MG | H15: 8 | I15: H | S15: J219 | T15: BRONQUIOLITIS AGUDA, NO ESPECIFICADA | U15: =+V15*(W15+X15+Y15+Z15) -> 792 | V15: 3.3 | W15: =IFERROR(VLOOKUP(VLOOKUP(E15,'Dosis Mx'!$R$1:$X$19,1,FALSE),'Dosis Mx'!$R$1:$X$19,6,FALSE),0) -> 90 | X15: =IFERROR(VLOOKUP(VLOOKUP(E15,'Dosis Mx'!$R$20:$X$36,1,FALSE),'Dosis Mx'!$R$20:$X$36,6,FALSE),0) -> 0 | Y15: =IFERROR(VLOOKUP(VLOOKUP(E15,'Dosis Mx'!$R$37:$X$54,1,FALSE),'Dosis Mx'!$R$37:$X$54,6,FALSE),0) -> 0 | Z15: =IFERROR(VLOOKUP(VLOOKUP(E15,'Dosis Mx'!$R$55:$X$78,1,FALSE),'Dosis Mx'!$R$55:$X$78,6,FALSE),0) -> 150 | AA15: =+F15*(24/H15) -> 450
A16: 13 | B16: UCE 05 | C16: 1040808764 | D16: YOBANIEL DAVID DOMICO PERNIA | E16: Vancomicina (Clorhidrato) 500 mg Polvo para Inyeccion | F16: 60 | G16: MG | H16: 6 | I16: H | S16: B86X | T16: ESCABIOSIS | U16: =+V16*(W16+X16+Y16+Z16) -> 792 | V16: 4.4 | W16: =IFERROR(VLOOKUP(VLOOKUP(E16,'Dosis Mx'!$R$1:$X$19,1,FALSE),'Dosis Mx'!$R$1:$X$19,6,FALSE),0) -> 0 | X16: =IFERROR(VLOOKUP(VLOOKUP(E16,'Dosis Mx'!$R$20:$X$36,1,FALSE),'Dosis Mx'!$R$20:$X$36,6,FALSE),0) -> 60 | Y16: =IFERROR(VLOOKUP(VLOOKUP(E16,'Dosis Mx'!$R$37:$X$54,1,FALSE),'Dosis Mx'!$R$37:$X$54,6,FALSE),0) -> 60 | Z16: =IFERROR(VLOOKUP(VLOOKUP(E16,'Dosis Mx'!$R$55:$X$78,1,FALSE),'Dosis Mx'!$R$55:$X$78,6,FALSE),0) -> 60 | AA16: =+F16*(24/H16) -> 240
A17: 14 | B17: UCI 06 | C17: 1078474669 | D17: CATALINA GONZALEZ TUNAY | E17: Cefepime 1000 mg Polvo para inyeccion | F17: 300 | G17: MG | H17: 8 | I17: H | S17: J158 | T17: OTRAS NEUMONIAS BACTERIANAS | U17: =+V17*(W17+X17+Y17+Z17) -> 1536 | V17: 6.4 | W17: =IFERROR(VLOOKUP(VLOOKUP(E17,'Dosis Mx'!$R$1:$X$19,1,FALSE),'Dosis Mx'!$R$1:$X$19,6,FALSE),0) -> 90 | X17: =IFERROR(VLOOKUP(VLOOKUP(E17,'Dosis Mx'!$R$20:$X$36,1,FALSE),'Dosis Mx'!$R$20:$X$36,6,FALSE),0) -> 0 | Y17: =IFERROR(VLOOKUP(VLOOKUP(E17,'Dosis Mx'!$R$37:$X$54,1,FALSE),'Dosis Mx'!$R$37:$X$54,6,FALSE),0) -> 0 | Z17: =IFERROR(VLOOKUP(VLOOKUP(E17,'Dosis Mx'!$R$55:$X$78,1,FALSE),'Dosis Mx'!$R$55:$X$78,6,FALSE),0) -> 150 | AA17: =+F17*(24/H17) -> 900
